<?xml version="1.0" encoding="utf-8" ?>

<robot name="jaka_zu3" xmlns:xacro="http://www.ros.org/wiki/xacro">
  <xacro:include filename="gazebo_control.xacro" />
  <xacro:include filename="camera.xacro" />
  <xacro:macro name="cylinder_inertial" params="radius length mass *origin">
    <inertial>
      <mass value="${mass}" />
      <xacro:insert_block name="origin" />
      <inertia ixx="${0.0833333 * mass * (3 * radius * radius + length * length)}" ixy="0.0" ixz="0.0"
        iyy="${0.0833333 * mass * (3 * radius * radius + length * length)}" iyz="0.0"
        izz="${0.5 * mass * radius * radius}" />
    </inertial>
  </xacro:macro>
  
  <xacro:property name="base_mass" value="2.0" />  <!-- This mass might be incorrect -->
  <xacro:property name="link1_mass" value="2.0" />
  <xacro:property name="link2_mass" value="3.42" />
  <xacro:property name="link3_mass" value="1.26" />
  <xacro:property name="link4_mass" value="0.8" />
  <xacro:property name="link5_mass" value="0.8" />
  <xacro:property name="link6_mass" value="0.35" />


  <!-- <link name="plain_link">
    <visual>
      <geometry>
        <box size="1 1 0.2" /> 
      </geometry>
      <origin xyz="0 0 0" rpy="0 0 0" />
      <material name="gray">
        <color rgba="0.8 0.8 0.8 1" />
      </material>
    </visual>
    <collision>
      <geometry>
        <box size="1 1 0.2" />
      </geometry>
      <origin xyz="0 0 0" rpy="0 0 0" />
    </collision>
    <inertial>
      <origin xyz="0 0 0" rpy="0 0 0" />
      <mass value="20.0" />
      <inertia ixx="1" ixy="0" ixz="0" iyy="0.9875" iyz="0" izz="1" />
    </inertial>
  </link>
  <gazebo reference="plain_link">
    <selfCollide>true</selfCollide>
  </gazebo>

  <joint name="plain2cylinder" type="fixed">
    <parent link="plain_link" />
    <child link="cylinder_link" />
    <origin xyz="0 0 0.2" rpy="0 0 0" />
  </joint>

  <link name="cylinder_link">
    <visual>
      <geometry>
        <cylinder radius="0.065" length="0.6" /> 
      </geometry>
      <origin xyz="0 0 0" rpy="0 0 0" />
      <material name="gray">
        <color rgba="0.8 0.8 0.8 1" />
      </material>
    </visual>
    <collision>
      <geometry>
        <cylinder radius="0.065" length="0.6" />
      </geometry>
      <origin xyz="0 0 0" rpy="0 0 0" />
    </collision>
    <inertial>
      <origin xyz="0 0 0" rpy="0 0 0" />
      <mass value="20.0" />
      <inertia ixx="1" ixy="0" ixz="0" iyy="0.9875" iyz="0" izz="1" />
    </inertial>
  </link>
  <gazebo reference="cylinder_link">
    <selfCollide>true</selfCollide>
  </gazebo>

  <joint name="cylinder2base" type="fixed">
    <parent link="cylinder_link" />
    <child link="base_link" />
    <origin xyz="0 0 0.2" rpy="0 0 0" />
  </joint> -->


  <link name="base_link">
    <inertial>
      <origin xyz="-0.0015666 1.7294E-05 0.05088" rpy="0 0 0" />
      <mass value="2.0" />
      <inertia ixx="1" ixy="0" ixz="0" iyy="1" iyz="0" izz="1" />
    </inertial>
    <!-- <xacro:cylinder_inertial radius="0.075" length="0.038" mass="${base_mass}">
        <origin xyz="0.0 0.0 0.0" rpy="0 0 0" />
    </xacro:cylinder_inertial> -->
    <visual>
      <origin xyz="0 0 0" rpy="0 0 0" />
      <geometry>
        <mesh filename="package://jaka_rviz/meshes/jaka_zu3_meshes/Link_0.STL" />
      </geometry>
      <material name="Grey">
        <color rgba="0.7 0.7 0.7 1.0" />
      </material>
    </visual>
    <collision>
      <origin xyz="0 0 0" rpy="0 0 0" />
      <geometry>
        <mesh filename="package://jaka_rviz/meshes/jaka_zu3_meshes/Link_0.STL" />
      </geometry>
    </collision>
  </link>
  <gazebo reference="base_link">
    <selfCollide>true</selfCollide>
  </gazebo>

  <link name="Link_1">
    <inertial>
      <origin xyz="-3.8197E-07 0.0039623 -0.0033438" rpy="0 0 0" />
      <mass value="2.0" />
      <inertia ixx="1" ixy="0" ixz="0" iyy="1" iyz="0" izz="1" />
    </inertial>
    <!-- <xacro:cylinder_inertial radius="0.075" length="0.175" mass="${link1_mass}">
        <origin xyz="0.0 0.0 0.0" rpy="0 0 0" />
    </xacro:cylinder_inertial> -->
    <visual>
      <origin xyz="0 0 0" rpy="0 0 0" />
      <geometry>
        <mesh filename="package://jaka_rviz/meshes/jaka_zu3_meshes/Link_1.STL" />
      </geometry>
      <material name="Grey">
        <color rgba="0.7 0.7 0.7 1.0" />
      </material>
    </visual>
    <collision>
      <origin xyz="0 0 0" rpy="0 0 0" />
      <geometry>
        <mesh filename="package://jaka_rviz/meshes/jaka_zu3_meshes/Link_1.STL" />
      </geometry>
    </collision>
  </link>
  <gazebo reference="Link_1">
    <selfCollide>true</selfCollide>
  </gazebo>

  <joint name="joint_1" type="revolute">
    <origin xyz="0 0 0.15055" rpy="0 0 0" />
    <parent link="base_link" />
    <child link="Link_1" />
    <axis xyz="0 0 -1" />
    <limit lower="-3.1415926" upper="3.1415926" effort="330" velocity="2.16" />
    <dynamics damping="50" friction="1" />
  </joint>

  <link name="Link_2">
    <inertial>
      <origin xyz="0.11439 -6.6036E-07 -0.11395" rpy="0 0 0" />
      <mass value="3.42" />
      <inertia ixx="1" ixy="0" ixz="0" iyy="1" iyz="0" izz="1" />
    </inertial>
    <!-- <xacro:cylinder_inertial radius="0.075" length="0.246" mass="${link2_mass}">
        <origin xyz="0.0 0.0 0.123" rpy="0 0 0" />
    </xacro:cylinder_inertial> -->
    <visual>
      <origin xyz="0 0 0" rpy="0 0 0" />
      <geometry>
        <mesh filename="package://jaka_rviz/meshes/jaka_zu3_meshes/Link_2.STL" />
      </geometry>
      <material name="Grey">
        <color rgba="0.7 0.7 0.7 1.0" />
      </material>
    </visual>
    <collision>
      <origin xyz="0 0 0" rpy="0 0 0" />
      <geometry>
        <mesh filename="package://jaka_rviz/meshes/jaka_zu3_meshes/Link_2.STL" />
      </geometry>
    </collision>
  </link>
  <gazebo reference="Link_2">
    <selfCollide>true</selfCollide>
  </gazebo> 

  <joint name="joint_2" type="revolute">
    <origin xyz="0 0 0" rpy="1.5708 0 0" />
    <parent link="Link_1" />
    <child link="Link_2" />
    <axis xyz="0 0 1" />
    <limit lower="-3.1415926" upper="3.1415926" effort="330" velocity="2.16" />
    <dynamics damping="50" friction="1" />
  </joint>

  <link name="Link_3">
    <inertial>
      <origin xyz="0.13218 1.2348E-05 -0.0083734" rpy="0 0 0" />
      <mass  value="1.26" />
      <inertia ixx="1" ixy="0" ixz="0" iyy="1" iyz="0" izz="1" />
    </inertial>
    <!-- <xacro:cylinder_inertial radius="0.075" length="0.228" mass="${link3_mass}">
        <origin xyz="0.0 0.0 0.114" rpy="0 0 0" />
    </xacro:cylinder_inertial> -->
    <visual>
      <origin xyz="0 0 0" rpy="0 0 0" />
      <geometry>
        <mesh filename="package://jaka_rviz/meshes/jaka_zu3_meshes/Link_3.STL" />
      </geometry>
      <material name="Grey">
        <color rgba="0.7 0.7 0.7 1.0" />
      </material>
    </visual>
    <collision>
      <origin xyz="0 0 0" rpy="0 0 0" />
      <geometry>
        <mesh filename="package://jaka_rviz/meshes/jaka_zu3_meshes/Link_3.STL" />
      </geometry>
    </collision>
  </link>
  <gazebo reference="Link_3">
    <selfCollide>true</selfCollide>
  </gazebo> 

  <joint name="joint_3" type="revolute">
    <origin xyz="0.248 0 0" rpy="0 0 0" />
    <parent link="Link_2" />
    <child link="Link_3" />
    <axis xyz="0 0 1" />
    <limit lower="-3.1415926" upper="3.1415926" effort="330" velocity="2.16" />
    <dynamics damping="50" friction="1" />
  </joint>

  <link name="Link_4">
    <inertial>
      <origin xyz="6.5068E-08 -0.014052 0.0031614" rpy="0 0 0" />
      <mass value="0.8" />
      <inertia ixx="1" ixy="0" ixz="0" iyy="1" iyz="0" izz="1" />
    </inertial>
    <!-- <xacro:cylinder_inertial radius="0.075" length="0.105" mass="${link4_mass}">
        <origin xyz="0.0 0.0 0.0" rpy="0 0 0" />
    </xacro:cylinder_inertial> -->
    <visual>
      <origin xyz="0 0 0" rpy="0 0 0" />
      <geometry>
        <mesh filename="package://jaka_rviz/meshes/jaka_zu3_meshes/Link_4.STL" />
      </geometry>
      <material name="Grey">
        <color rgba="0.7 0.7 0.7 1.0" />
      </material>
    </visual>
    <collision>
      <origin xyz="0 0 0" rpy="0 0 0" />
      <geometry>
        <mesh filename="package://jaka_rviz/meshes/jaka_zu3_meshes/Link_4.STL" />
      </geometry>
    </collision>
  </link>
  <gazebo reference="Link_4">
    <selfCollide>true</selfCollide>
  </gazebo>

  <joint name="joint_4" type="revolute">
    <origin xyz="0.228 1.1925E-05 -0.115" rpy="0 0 0" />
    <parent link="Link_3" />
    <child link="Link_4" />
    <axis xyz="0 0 1" />
    <limit lower="-3.1415926" upper="3.1415926" effort="330" velocity="2.16" />
    <dynamics damping="50" friction="1" />
  </joint>

  <link name="Link_5">
    <inertial>
      <origin xyz="7.9256E-08 0.0068655 -0.0029086" rpy="0 0 0" />
      <mass value="0.8" />
      <inertia ixx="1" ixy="0" ixz="0" iyy="1" iyz="0" izz="1" />
    </inertial>
    <!-- <xacro:cylinder_inertial radius="0.075" length="0.1175" mass="${link5_mass}">
        <origin xyz="0.0 0.0 0.0" rpy="0 0 0" />
    </xacro:cylinder_inertial> -->
    <visual>
      <origin xyz="0 0 0" rpy="0 0 0" />
      <geometry>
        <mesh filename="package://jaka_rviz/meshes/jaka_zu3_meshes/Link_5.STL" />
      </geometry>
      <material name="Grey">
        <color rgba="0.7 0.7 0.7 1.0" />
      </material>
    </visual>
    <collision>
      <origin xyz="0 0 0" rpy="0 0 0" />
      <geometry>
        <mesh filename="package://jaka_rviz/meshes/jaka_zu3_meshes/Link_5.STL" />
      </geometry>
    </collision>
  </link>
  <gazebo reference="Link_5">
    <selfCollide>true</selfCollide>
  </gazebo>

  <joint name="joint_5" type="revolute">
    <origin xyz="0 -0.1175 0" rpy="1.5708 0 0" />
    <parent link="Link_4" />
    <child link="Link_5" />
    <axis xyz="0 0 -1" />
    <limit lower="-3.1415926" upper="3.1415926" effort="330" velocity="2.16" />
    <dynamics damping="50" friction="1" />
  </joint>

  <link name="Link_6">
    <inertial>
      <origin xyz="4.9731E-05 -2.965E-05 -0.016372" rpy="0 0 0" />
      <mass value="0.35" />
      <inertia ixx="1" ixy="0" ixz="0" iyy="1" iyz="0" izz="1" />
    </inertial>
    <!-- <xacro:cylinder_inertial radius="0.075" length="0.105" mass="${link6_mass}">
        <origin xyz="0.0 0.0 0.0" rpy="0 0 0" />
    </xacro:cylinder_inertial> -->
    <visual>
      <origin xyz="0 0 0" rpy="0 0 0" />
      <geometry>
        <mesh filename="package://jaka_rviz/meshes/jaka_zu3_meshes/Link_6.STL" />
      </geometry>
      <material name="Grey">
        <color rgba="0.7 0.7 0.7 1.0" />
      </material>
    </visual>
    <collision>
      <origin xyz="0 0 0" rpy="0 0 0" />
      <geometry>
        <mesh filename="package://jaka_rviz/meshes/jaka_zu3_meshes/Link_6.STL" />
      </geometry>
    </collision>
  </link>
  <gazebo reference="Link_6">
    <selfCollide>true</selfCollide>
  </gazebo>

  <joint name="joint_6" type="revolute">
    <origin xyz="0 0.1065 0" rpy="-1.5708 0 0" />
    <parent link="Link_5" />
    <child link="Link_6" />
    <axis xyz="0 0 -1" />
    <limit lower="-3.1415926" upper="3.1415926" effort="330" velocity="2.16" />
    <dynamics damping="50" friction="1" />
  </joint>

  <!-- camera_link -->
  <link name="camera_link">
    <visual>
      <geometry>
        <box size="0.01 0.025 0.025" />
      </geometry>
      <origin xyz="0.0 0.0 0.0" rpy="0.0 0.0 0.0" />
      <meterial name="black" />
    </visual>
  </link>

  <joint name="camera_joint" type="fixed" >
    <parent link="Link_6" />
    <child link="camera_link" />
    <origin xyz="0 0 0" rpy="0 0 0" />
  </joint>
  <!-- ##################### -->

  <link name="world" />

  <joint name="world_joint" type="fixed">
    <parent link="world" />
    <child link = "base_link" />
    <origin xyz="0.0 0.0 0.0" rpy="0.0 0.0 0.0" />
  </joint>


  <xacro:macro name="arm_transmission" params="joint_name">

      <transmission name="trans">
          <type>transmission_interface/SimpleTransmission</type>
          <joint name="${joint_name}">
            <hardwareInterface>hardware_interface/PositionJointInterface</hardwareInterface>
          </joint>
          <actuator name="motor">
            <hardwareInterface>hardware_interface/PositionJointInterface</hardwareInterface>
            <mechanicalReduction>1</mechanicalReduction>
          </actuator>
      </transmission>
  </xacro:macro>

    <xacro:arm_transmission joint_name='joint_1' />
    <xacro:arm_transmission joint_name='joint_2' />
    <xacro:arm_transmission joint_name='joint_3' />
    <xacro:arm_transmission joint_name='joint_4' />
    <xacro:arm_transmission joint_name='joint_5' />
    <xacro:arm_transmission joint_name='joint_6' />

</robot>
