<?xml version="1.0" encoding="utf-8" ?>
<!-- =================================================================================== -->
<!-- |    This document was autogenerated by xacro from /home/axin/jaka_ws/src/jaka_zu3_myurdf/urdf/test.xacro | -->
<!-- |    EDITING THIS FILE BY HAND IS NOT RECOMMENDED                                 | -->
<!-- =================================================================================== -->
<robot name="jaka_zu3">
    <gazebo>
        <plugin filename="libgazebo_ros_control.so" name="gazebo_ros_control">
            <robotNamespace>/jaka_zu3</robotNamespace>
            <!-- <robotSimType>gazebo_ros_control/DefaultRobotHWSim</robotSimType>
        <legacyModeNS>true</legacyModeNS> -->
        </plugin>
    </gazebo>
    <link name="base_footprint">
        <visual>
            <geometry>
                <sphere radius="0.001" />
            </geometry>
            <oringin rpy="0 0 0" xyz="0 0 0" />
        </visual>
    </link>
    <gazebo reference="base_footprint">
        <meterial>Gazebo/Grey</meterial>
    </gazebo>
    <link name="plain_link">
        <visual>
            <origin rpy="0 0 0" xyz="0 0 0" />
            <geometry>
                <box size="0.4 0.4 0.1" />
                <origin rpy="0 0 0" xyz="0 0 0" />
            </geometry>
            <material name="plaincolor">
                <color rgba="0.84706 0.84706 0.84706 1" />
            </material>
        </visual>
        <collision>
            <origin rpy="0 0 0" xyz="0 0 0" />
            <geometry>
                <box size="0.4 0.4 0.1" />
            </geometry>
        </collision>
        
<inertial>
            <origin rpy="0 0 0" xyz="0 0 0" />
            <mass value="50.0" />
            <inertia ixx="0.70833" ixy="0.0" ixz="0.0" iyy="1.33333" iyz="0.0" izz="0.70833" />
        </inertial>

    </link>
    <gazebo reference="plain_link">
        <meterial>Gazebo/Grey</meterial>
    </gazebo>
    <joint name="base2plain" type="fixed">
        <parent link="base_footprint" />
        <child link="plain_link" />
        <origin rpy="0 0 0" xyz="0 0 0.05" />
    </joint>
    <link name="cylinder_link">
        <visual>
            <geometry>
                <cylinder length="0.6" radius="0.065" />
            </geometry>
            <origin rpy="0 0 0" xyz="0 0 0" />
            <material name="gray">
                <color rgba="0.8 0.8 0.8 1" />
            </material>
        </visual>
        <collision>
            <geometry>
                <cylinder length="0.6" radius="0.065" />
            </geometry>
            <origin rpy="0 0 0" xyz="0 0 0" />
        </collision>
        
<inertial>
            <origin rpy="0 0 0" xyz="0 0 0" />
            <mass value="20.0" />
            <inertia ixx="0.621125" ixy="0.0" ixz="0.0" iyy="0.621125" iyz="0.0" izz="4.225" />
        </inertial>

    </link>
    <gazebo reference="plain_link">
        <meterial>Gazebo/Grey</meterial>
    </gazebo>
    <joint name="plain2cylinder" type="fixed">
        <parent link="plain_link" />
        <child link="cylinder_link" />
        <origin rpy="0 0 0" xyz="0 0 0.35" />
    </joint>
    <link name="Link_0">
        
<inertial>
            <origin rpy="0 0 0" xyz="0 0 0" />
            <mass value="0.46393" />
            <inertia ixx="0.00064494" ixy="-1.0227E-07" ixz="-1.0724E-05" iyy="0.00065157" iyz="3.7859E-07" izz="0.00083278" />
        </inertial>

        <visual>
            <origin rpy="0 0 0" xyz="0.0 0.0 0" />
            <geometry>
                <mesh filename="package://jaka_zu3_myurdf/meshes/Link_0.STL" />
            </geometry>
            <material name="Link_0Color">
                <color rgba="0.84706 0.84706 0.84706 1" />
            </material>
        </visual>
        <collision>
            <origin rpy="0 0 0" xyz="0 0 0" />
            <geometry>
                <mesh filename="package://jaka_zu3_myurdf/meshes/Link_0.STL" />
            </geometry>
        </collision>
    </link>
    <gazebo reference="Link_0">
        <meterial>Gazebo/Grey</meterial>
    </gazebo>
    <joint name="cylinder2base" type="fixed">
        <parent link="cylinder_link" />
        <child link="Link_0" />
        <origin rpy="0 0 0" xyz="0 0 0.3" />
    </joint>
    <link name="Link_1">
        
<inertial>
            <origin rpy="0 0 0" xyz="0 0 0" />
            <mass value="0.88365" />
            <inertia ixx="0.0015634" ixy="1.5495E-08" ixz="5.6443E-09" iyy="0.0015047" iyz="-9.0168E-06" izz="0.0010527" />
        </inertial>

        <visual>
            <origin rpy="0 0 0" xyz="0 0 0" />
            <geometry>
                <mesh filename="package://jaka_zu3_myurdf/meshes/Link_1.STL" />
            </geometry>
            <material name="Link_1Color">
                <color rgba="1 1 1 1" />
            </material>
        </visual>
        <collision>
            <origin rpy="0 0 0" xyz="0 0 0" />
            <geometry>
                <mesh filename="package://jaka_zu3_myurdf/meshes/Link_1.STL" />
            </geometry>
        </collision>
    </link>
    <gazebo reference="Link_1">
        <meterial>Gazebo/Grey</meterial>
    </gazebo>
    <joint name="joint_1" type="revolute">
        <origin rpy="0 0 0" xyz="0 0 0.15055" />
        <parent link="Link_0" />
        <child link="Link_1" />
        <axis xyz="0 0 1" />
        <limit effort="300" lower="-4.71" upper="4.71" velocity="3.14" />
        <dynamics damping="50" friction="1" />
    </joint>
    <transmission name="trans1">
        <type>transmission_interface/SimpleTransmission</type>
        <joint name="joint_1">
            <hardwareInterface>hardware_interface/EffortJointInterface</hardwareInterface>
        </joint>
        <actuator name="motor1">
            <hardwareInterface>hardware_interface/EffortJointInterface</hardwareInterface>
            <mechanicalReduction>1</mechanicalReduction>
        </actuator>
    </transmission>
    <link name="Link_2">
        
<inertial>
            <origin rpy="0 0 0" xyz="0.114 -5.5358E-07 -0.11162" />
            <mass value="2.3202" />
            <inertia ixx="1" ixy="0" ixz="0" iyy="1" iyz="0" izz="1" />
        </inertial>

        <visual>
            <origin rpy="0 0 0" xyz="0 0 0" />
            <geometry>
                <mesh filename="package://jaka_zu3_myurdf/meshes/Link_2.STL" />
            </geometry>
            <material name="Link_2Color">
                <color rgba="1 1 1 1" />
            </material>
        </visual>
        <collision>
            <origin rpy="0 0 0" xyz="0 0 0" />
            <geometry>
                <mesh filename="package://jaka_zu3_myurdf/meshes/Link_2.STL" />
            </geometry>
        </collision>
    </link>
    <gazebo reference="Link_2">
        <meterial>Gazebo/Grey</meterial>
    </gazebo>
    <joint name="joint_2" type="revolute">
        <origin rpy="1.5708 0 0" xyz="0 0 0" />
        <parent link="Link_1" />
        <child link="Link_2" />
        <axis xyz="0 0 1" />
        <limit effort="300" lower="-1.48" upper="4.62" velocity="3.14" />
        <dynamics damping="50" friction="1" />
    </joint>
    <transmission name="trans2">
        <type>transmission_interface/SimpleTransmission</type>
        <joint name="joint_2">
            <hardwareInterface>hardware_interface/EffortJointInterface</hardwareInterface>
        </joint>
        <actuator name="motor2">
            <hardwareInterface>hardware_interface/EffortJointInterface</hardwareInterface>
            <mechanicalReduction>1</mechanicalReduction>
        </actuator>
    </transmission>
    <link name="Link_3">
        
<inertial>
            <origin rpy="0 0 0" xyz="0 0 0" />
            <mass value="1.2034" />
            <inertia ixx="1" ixy="0" ixz="0" iyy="1" iyz="0" izz="1" />
        </inertial>

        <visual>
            <origin rpy="0 0 0" xyz="0 0 0" />
            <geometry>
                <mesh filename="package://jaka_zu3_myurdf/meshes/Link_3.STL" />
            </geometry>
            <material name="Link_3Color">
                <color rgba="1 1 1 1" />
            </material>
        </visual>
        <collision>
            <origin rpy="0 0 0" xyz="0 0 0" />
            <geometry>
                <mesh filename="package://jaka_zu3_myurdf/meshes/Link_3.STL" />
            </geometry>
        </collision>
    </link>
    <gazebo reference="Link_3">
        <meterial>Gazebo/Grey</meterial>
    </gazebo>
    <joint name="joint_3" type="revolute">
        <origin rpy="0 0 0" xyz="0.246 0 0" />
        <parent link="Link_2" />
        <child link="Link_3" />
        <axis xyz="0 0 1" />
        <limit effort="330" lower="-3.05" upper="3.05" velocity="3.14" />
        <dynamics damping="50" friction="1" />
    </joint>
    <transmission name="trans3">
        <type>transmission_interface/SimpleTransmission</type>
        <joint name="joint_3">
            <hardwareInterface>hardware_interface/EffortJointInterface</hardwareInterface>
        </joint>
        <actuator name="motor3">
            <hardwareInterface>hardware_interface/EffortJointInterface</hardwareInterface>
            <mechanicalReduction>1</mechanicalReduction>
        </actuator>
    </transmission>
    <link name="Link_4">
        
<inertial>
            <origin rpy="0 0 0" xyz="6.5395E-08 -0.014051 0.0031609" />
            <mass value="0.49334" />
            <inertia ixx="1" ixy="0" ixz="0" iyy="1" iyz="0" izz="1" />
        </inertial>

        <visual>
            <origin rpy="0 0 0" xyz="0 0 0" />
            <geometry>
                <mesh filename="package://jaka_zu3_myurdf/meshes/Link_4.STL" />
            </geometry>
            <material name="Link_4Color">
                <color rgba="1 1 1 1" />
            </material>
        </visual>
        <collision>
            <origin rpy="0 0 0" xyz="0 0 0" />
            <geometry>
                <mesh filename="package://jaka_zu3_myurdf/meshes/Link_4.STL" />
            </geometry>
        </collision>
    </link>
    <gazebo reference="Link_4">
        <meterial>Gazebo/Grey</meterial>
    </gazebo>
    <joint name="joint_4" type="revolute">
        <origin rpy="0 0 0" xyz="0.228 0 -0.113" />
        <parent link="Link_3" />
        <child link="Link_4" />
        <axis xyz="0 0 1" />
        <limit effort="330" lower="-1.48" upper="4.62" velocity="3.14" />
        <dynamics damping="50" friction="1" />
    </joint>
    <transmission name="trans4">
        <type>transmission_interface/SimpleTransmission</type>
        <joint name="joint_4">
            <hardwareInterface>hardware_interface/EffortJointInterface</hardwareInterface>
        </joint>
        <actuator name="motor4">
            <hardwareInterface>hardware_interface/EffortJointInterface</hardwareInterface>
            <mechanicalReduction>1</mechanicalReduction>
        </actuator>
    </transmission>
    <link name="Link_5">
        
<inertial>
            <origin rpy="0 0 0" xyz="2.5684E-07 0.0068642 -0.0021581" />
            <mass value="0.55082" />
            <inertia ixx="1" ixy="0" ixz="0" iyy="1" iyz="0" izz="1" />
        </inertial>

        <visual>
            <origin rpy="0 0 0" xyz="0 0 0" />
            <geometry>
                <mesh filename="package://jaka_zu3_myurdf/meshes/Link_5.STL" />
            </geometry>
            <material name="Link_5Color">
                <color rgba="1 1 1 1" />
            </material>
        </visual>
        <collision>
            <origin rpy="0 0 0" xyz="0 0 0" />
            <geometry>
                <mesh filename="package://jaka_zu3_myurdf/meshes/Link_5.STL" />
            </geometry>
        </collision>
    </link>
    <gazebo reference="Link_5">
        <meterial>Gazebo/Grey</meterial>
    </gazebo>
    <joint name="joint_5" type="revolute">
        <origin rpy="1.5708 0 0" xyz="0 -0.11675 0" />
        <parent link="Link_4" />
        <child link="Link_5" />
        <axis xyz="0 0 1" />
        <limit effort="330" lower="-4.71" upper="4.71" velocity="3.83" />
        <dynamics damping="50" friction="1" />
    </joint>
    <transmission name="trans5">
        <type>transmission_interface/SimpleTransmission</type>
        <joint name="joint_5">
            <hardwareInterface>hardware_interface/EffortJointInterface</hardwareInterface>
        </joint>
        <actuator name="motor5">
            <hardwareInterface>hardware_interface/EffortJointInterface</hardwareInterface>
            <mechanicalReduction>1</mechanicalReduction>
        </actuator>
    </transmission>
    <link name="Link_6">
        
<inertial>
            <origin rpy="0 0 0" xyz="5.2572E-05 -0.0001007 -0.0091035" />
            <mass value="0.094884" />
            <inertia ixx="1" ixy="0" ixz="0" iyy="1" iyz="0" izz="1" />
        </inertial>

        <visual>
            <origin rpy="0 0 0" xyz="0 0 0" />
            <geometry>
                <mesh filename="package://jaka_zu3_myurdf/meshes/Link_6.STL" />
            </geometry>
            <material name="Link_6Color">
                <color rgba="1 1 1 1" />
            </material>
        </visual>
        <collision>
            <origin rpy="0 0 0" xyz="0 0 0" />
            <geometry>
                <mesh filename="package://jaka_zu3_myurdf/meshes/Link_6.STL" />
            </geometry>
        </collision>
    </link>
    <gazebo reference="Link_6">
        <meterial>Gazebo/Grey</meterial>
    </gazebo>
    <joint name="joint_6" type="revolute">
        <origin rpy="-1.5708 0 0" xyz="0 0.0985 0" />
        <parent link="Link_5" />
        <child link="Link_6" />
        <axis xyz="0 0 -1" />
        <limit effort="330" lower="-6.283185" upper="6.283185" velocity="3.14" />
        <dynamics damping="50" friction="1" />
    </joint>
    <transmission name="trans6">
        <type>transmission_interface/SimpleTransmission</type>
        <joint name="joint_6">
            <hardwareInterface>hardware_interface/EffortJointInterface</hardwareInterface>
        </joint>
        <actuator name="motor6">
            <hardwareInterface>hardware_interface/EffortJointInterface</hardwareInterface>
            <mechanicalReduction>1</mechanicalReduction>
        </actuator>
    </transmission>
    <transmission name="trans_joint_1">
        <type>transmission_interface/SimpleTransmission</type>
        <joint name="joint_1">
            <hardwareInterface>hardware_interface/EffortJointInterface</hardwareInterface>
        </joint>
        <actuator name="joint_1_motor">
            <hardwareInterface>hardware_interface/EffortJointInterface</hardwareInterface>
            <mechanicalReduction>1</mechanicalReduction>
        </actuator>
    </transmission>
    <transmission name="trans_joint_2">
        <type>transmission_interface/SimpleTransmission</type>
        <joint name="joint_2">
            <hardwareInterface>hardware_interface/EffortJointInterface</hardwareInterface>
        </joint>
        <actuator name="joint_2_motor">
            <hardwareInterface>hardware_interface/EffortJointInterface</hardwareInterface>
            <mechanicalReduction>1</mechanicalReduction>
        </actuator>
    </transmission>
    <transmission name="trans_joint_3">
        <type>transmission_interface/SimpleTransmission</type>
        <joint name="joint_3">
            <hardwareInterface>hardware_interface/EffortJointInterface</hardwareInterface>
        </joint>
        <actuator name="joint_3_motor">
            <hardwareInterface>hardware_interface/EffortJointInterface</hardwareInterface>
            <mechanicalReduction>1</mechanicalReduction>
        </actuator>
    </transmission>
    <transmission name="trans_joint_4">
        <type>transmission_interface/SimpleTransmission</type>
        <joint name="joint_4">
            <hardwareInterface>hardware_interface/EffortJointInterface</hardwareInterface>
        </joint>
        <actuator name="joint_4_motor">
            <hardwareInterface>hardware_interface/EffortJointInterface</hardwareInterface>
            <mechanicalReduction>1</mechanicalReduction>
        </actuator>
    </transmission>
    <transmission name="trans_joint_5">
        <type>transmission_interface/SimpleTransmission</type>
        <joint name="joint_5">
            <hardwareInterface>hardware_interface/EffortJointInterface</hardwareInterface>
        </joint>
        <actuator name="joint_5_motor">
            <hardwareInterface>hardware_interface/EffortJointInterface</hardwareInterface>
            <mechanicalReduction>1</mechanicalReduction>
        </actuator>
    </transmission>
    <transmission name="trans_joint_6">
        <type>transmission_interface/SimpleTransmission</type>
        <joint name="joint_6">
            <hardwareInterface>hardware_interface/EffortJointInterface</hardwareInterface>
        </joint>
        <actuator name="joint_6_motor">
            <hardwareInterface>hardware_interface/EffortJointInterface</hardwareInterface>
            <mechanicalReduction>1</mechanicalReduction>
        </actuator>
    </transmission>
    <gazebo>
        <plugin name="gazebo_ros_control" filename="libgazebo_ros_control.so">
            <robotNamespace>/</robotNamespace>
        </plugin>
    </gazebo>
</robot>

<transmission name="trans1">
        <type>transmission_interface/SimpleTransmission</type>
        <joint name="joint_1">
            <hardwareInterface>hardware_interface/EffortJointInterface</hardwareInterface>
        </joint>
        <actuator name="motor1">
            <hardwareInterface>hardware_interface/EffortJointInterface</hardwareInterface>
            <mechanicalReduction>1</mechanicalReduction>
        </actuator>
    </transmission>
    <link name="Link_2">
        <inertial>
            <origin rpy="0 0 0" xyz="0.114 -5.5358E-07 -0.11162" />
            <mass value="2.3202" />
            <inertia ixx="1" ixy="0" ixz="0" iyy="1" iyz="0" izz="1" />
        </inertial>
        <visual>
            <origin rpy="0 0 0" xyz="0 0 0" />
            <geometry>
                <mesh filename="package://jaka_zu3_myurdf/meshes/Link_2.STL" />
            </geometry>
            <material name="Link_2Color">
                <color rgba="1 1 1 1" />
            </material>
        </visual>
        <collision>
            <origin rpy="0 0 0" xyz="0 0 0" />
            <geometry>
                <mesh filename="package://jaka_zu3_myurdf/meshes/Link_2.STL" />
            </geometry>
        </collision>
    </link>
    <gazebo reference="Link_2">
        <meterial>Gazebo/Grey</meterial>
    </gazebo>
    <joint name="joint_2" type="revolute">
        <origin rpy="1.5708 0 0" xyz="0 0 0" />
        <parent link="Link_1" />
        <child link="Link_2" />
        <axis xyz="0 0 1" />
        <limit effort="300" lower="-1.48" upper="4.62" velocity="3.14" />
        <dynamics damping="50" friction="1" />
    </joint>
    <transmission name="trans2">
        <type>transmission_interface/SimpleTransmission</type>
        <joint name="joint_2">
            <hardwareInterface>hardware_interface/EffortJointInterface</hardwareInterface>
        </joint>
        <actuator name="motor2">
            <hardwareInterface>hardware_interface/EffortJointInterface</hardwareInterface>
            <mechanicalReduction>1</mechanicalReduction>
        </actuator>
    </transmission>
    <link name="Link_3">
        <inertial>
            <origin rpy="0 0 0" xyz="0 0 0" />
            <mass value="1.2034" />
            <inertia ixx="1" ixy="0" ixz="0" iyy="1" iyz="0" izz="1" />
        </inertial>
        <visual>
            <origin rpy="0 0 0" xyz="0 0 0" />
            <geometry>
                <mesh filename="package://jaka_zu3_myurdf/meshes/Link_3.STL" />
            </geometry>
            <material name="Link_3Color">
                <color rgba="1 1 1 1" />
            </material>
        </visual>
        <collision>
            <origin rpy="0 0 0" xyz="0 0 0" />
            <geometry>
                <mesh filename="package://jaka_zu3_myurdf/meshes/Link_3.STL" />
            </geometry>
        </collision>
    </link>
    <gazebo reference="Link_3">
        <meterial>Gazebo/Grey</meterial>
    </gazebo>
    <joint name="joint_3" type="revolute">
        <origin rpy="0 0 0" xyz="0.246 0 0" />
        <parent link="Link_2" />
        <child link="Link_3" />
        <axis xyz="0 0 1" />
        <limit effort="330" lower="-3.05" upper="3.05" velocity="3.14" />
        <dynamics damping="50" friction="1" />
    </joint>
    <transmission name="trans3">
        <type>transmission_interface/SimpleTransmission</type>
        <joint name="joint_3">
            <hardwareInterface>hardware_interface/EffortJointInterface</hardwareInterface>
        </joint>
        <actuator name="motor3">
            <hardwareInterface>hardware_interface/EffortJointInterface</hardwareInterface>
            <mechanicalReduction>1</mechanicalReduction>
        </actuator>
    </transmission>
    <link name="Link_4">
        <inertial>
            <origin rpy="0 0 0" xyz="6.5395E-08 -0.014051 0.0031609" />
            <mass value="0.49334" />
            <inertia ixx="1" ixy="0" ixz="0" iyy="1" iyz="0" izz="1" />
        </inertial>
        <visual>
            <origin rpy="0 0 0" xyz="0 0 0" />
            <geometry>
                <mesh filename="package://jaka_zu3_myurdf/meshes/Link_4.STL" />
            </geometry>
            <material name="Link_4Color">
                <color rgba="1 1 1 1" />
            </material>
        </visual>
        <collision>
            <origin rpy="0 0 0" xyz="0 0 0" />
            <geometry>
                <mesh filename="package://jaka_zu3_myurdf/meshes/Link_4.STL" />
            </geometry>
        </collision>
    </link>
    <gazebo reference="Link_4">
        <meterial>Gazebo/Grey</meterial>
    </gazebo>
    <joint name="joint_4" type="revolute">
        <origin rpy="0 0 0" xyz="0.228 0 -0.113" />
        <parent link="Link_3" />
        <child link="Link_4" />
        <axis xyz="0 0 1" />
        <limit effort="330" lower="-1.48" upper="4.62" velocity="3.14" />
        <dynamics damping="50" friction="1" />
    </joint>
    <transmission name="trans4">
        <type>transmission_interface/SimpleTransmission</type>
        <joint name="joint_4">
            <hardwareInterface>hardware_interface/EffortJointInterface</hardwareInterface>
        </joint>
        <actuator name="motor4">
            <hardwareInterface>hardware_interface/EffortJointInterface</hardwareInterface>
            <mechanicalReduction>1</mechanicalReduction>
        </actuator>
    </transmission>
    <link name="Link_5">
        <inertial>
            <origin rpy="0 0 0" xyz="2.5684E-07 0.0068642 -0.0021581" />
            <mass value="0.55082" />
            <inertia ixx="1" ixy="0" ixz="0" iyy="1" iyz="0" izz="1" />
        </inertial>
        <visual>
            <origin rpy="0 0 0" xyz="0 0 0" />
            <geometry>
                <mesh filename="package://jaka_zu3_myurdf/meshes/Link_5.STL" />
            </geometry>
            <material name="Link_5Color">
                <color rgba="1 1 1 1" />
            </material>
        </visual>
        <collision>
            <origin rpy="0 0 0" xyz="0 0 0" />
            <geometry>
                <mesh filename="package://jaka_zu3_myurdf/meshes/Link_5.STL" />
            </geometry>
        </collision>
    </link>
    <gazebo reference="Link_5">
        <meterial>Gazebo/Grey</meterial>
    </gazebo>
    <joint name="joint_5" type="revolute">
        <origin rpy="1.5708 0 0" xyz="0 -0.11675 0" />
        <parent link="Link_4" />
        <child link="Link_5" />
        <axis xyz="0 0 1" />
        <limit effort="330" lower="-4.71" upper="4.71" velocity="3.83" />
        <dynamics damping="50" friction="1" />
    </joint>
    <transmission name="trans5">
        <type>transmission_interface/SimpleTransmission</type>
        <joint name="joint_5">
            <hardwareInterface>hardware_interface/EffortJointInterface</hardwareInterface>
        </joint>
        <actuator name="motor5">
            <hardwareInterface>hardware_interface/EffortJointInterface</hardwareInterface>
            <mechanicalReduction>1</mechanicalReduction>
        </actuator>
    </transmission>
    <link name="Link_6">
        <inertial>
            <origin rpy="0 0 0" xyz="5.2572E-05 -0.0001007 -0.0091035" />
            <mass value="0.094884" />
            <inertia ixx="1" ixy="0" ixz="0" iyy="1" iyz="0" izz="1" />
        </inertial>
        <visual>
            <origin rpy="0 0 0" xyz="0 0 0" />
            <geometry>
                <mesh filename="package://jaka_zu3_myurdf/meshes/Link_6.STL" />
            </geometry>
            <material name="Link_6Color">
                <color rgba="1 1 1 1" />
            </material>
        </visual>
        <collision>
            <origin rpy="0 0 0" xyz="0 0 0" />
            <geometry>
                <mesh filename="package://jaka_zu3_myurdf/meshes/Link_6.STL" />
            </geometry>
        </collision>
    </link>
    <gazebo reference="Link_6">
        <meterial>Gazebo/Grey</meterial>
    </gazebo>
    <joint name="joint_6" type="revolute">
        <origin rpy="-1.5708 0 0" xyz="0 0.0985 0" />
        <parent link="Link_5" />
        <child link="Link_6" />
        <axis xyz="0 0 -1" />
        <limit effort="330" lower="-6.283185" upper="6.283185" velocity="3.14" />
        <dynamics damping="50" friction="1" />
    </joint>
    <transmission name="trans6">
        <type>transmission_interface/SimpleTransmission</type>
        <joint name="joint_6">
            <hardwareInterface>hardware_interface/EffortJointInterface</hardwareInterface>
        </joint>
        <actuator name="motor6">
            <hardwareInterface>hardware_interface/EffortJointInterface</hardwareInterface>
            <mechanicalReduction>1</mechanicalReduction>
        </actuator>
    </transmission>
    <transmission name="trans_joint_1">
        <type>transmission_interface/SimpleTransmission</type>
        <joint name="joint_1">
            <hardwareInterface>hardware_interface/EffortJointInterface</hardwareInterface>
        </joint>
        <actuator name="joint_1_motor">
            <hardwareInterface>hardware_interface/EffortJointInterface</hardwareInterface>
            <mechanicalReduction>1</mechanicalReduction>
        </actuator>
    </transmission>
    <transmission name="trans_joint_2">
        <type>transmission_interface/SimpleTransmission</type>
        <joint name="joint_2">
            <hardwareInterface>hardware_interface/EffortJointInterface</hardwareInterface>
        </joint>
        <actuator name="joint_2_motor">
            <hardwareInterface>hardware_interface/EffortJointInterface</hardwareInterface>
            <mechanicalReduction>1</mechanicalReduction>
        </actuator>
    </transmission>
    <transmission name="trans_joint_3">
        <type>transmission_interface/SimpleTransmission</type>
        <joint name="joint_3">
            <hardwareInterface>hardware_interface/EffortJointInterface</hardwareInterface>
        </joint>
        <actuator name="joint_3_motor">
            <hardwareInterface>hardware_interface/EffortJointInterface</hardwareInterface>
            <mechanicalReduction>1</mechanicalReduction>
        </actuator>
    </transmission>
    <transmission name="trans_joint_4">
        <type>transmission_interface/SimpleTransmission</type>
        <joint name="joint_4">
            <hardwareInterface>hardware_interface/EffortJointInterface</hardwareInterface>
        </joint>
        <actuator name="joint_4_motor">
            <hardwareInterface>hardware_interface/EffortJointInterface</hardwareInterface>
            <mechanicalReduction>1</mechanicalReduction>
        </actuator>
    </transmission>
    <transmission name="trans_joint_5">
        <type>transmission_interface/SimpleTransmission</type>
        <joint name="joint_5">
            <hardwareInterface>hardware_interface/EffortJointInterface</hardwareInterface>
        </joint>
        <actuator name="joint_5_motor">
            <hardwareInterface>hardware_interface/EffortJointInterface</hardwareInterface>
            <mechanicalReduction>1</mechanicalReduction>
        </actuator>
    </transmission>
    <transmission name="trans_joint_6">
        <type>transmission_interface/SimpleTransmission</type>
        <joint name="joint_6">
            <hardwareInterface>hardware_interface/EffortJointInterface</hardwareInterface>
        </joint>
        <actuator name="joint_6_motor">
            <hardwareInterface>hardware_interface/EffortJointInterface</hardwareInterface>
            <mechanicalReduction>1</mechanicalReduction>
        </actuator>
    </transmission>
    <gazebo>
        <plugin name="gazebo_ros_control" filename="libgazebo_ros_control.so">
            <robotNamespace>/</robotNamespace>
        </plugin>
    </gazebo>
</robot>
<?xml version="1.0" encoding="utf-8" ?>
<!-- =================================================================================== -->
<!-- |    This document was autogenerated by xacro from /home/axin/jaka_ws/src/jaka_zu3_myurdf/urdf/test.xacro | -->
<!-- |    EDITING THIS FILE BY HAND IS NOT RECOMMENDED                                 | -->
<!-- =================================================================================== -->
<robot name="jaka_zu3">
    <gazebo>
        <plugin filename="libgazebo_ros_control.so" name="gazebo_ros_control">
            <robotNamespace>/jaka_zu3</robotNamespace>
            <!-- <robotSimType>gazebo_ros_control/DefaultRobotHWSim</robotSimType>
        <legacyModeNS>true</legacyModeNS> -->
        </plugin>
    </gazebo>
    <link name="base_footprint">
        <visual>
            <geometry>
                <sphere radius="0.001" />
            </geometry>
            <oringin rpy="0 0 0" xyz="0 0 0" />
        </visual>
    </link>
    <gazebo reference="base_footprint">
        <meterial>Gazebo/Grey</meterial>
    </gazebo>
    <link name="plain_link">
        <visual>
            <origin rpy="0 0 0" xyz="0 0 0" />
            <geometry>
                <box size="0.4 0.4 0.1" />
                <origin rpy="0 0 0" xyz="0 0 0" />
            </geometry>
            <material name="plaincolor">
                <color rgba="0.84706 0.84706 0.84706 1" />
            </material>
        </visual>
        <collision>
            <origin rpy="0 0 0" xyz="0 0 0" />
            <geometry>
                <box size="0.4 0.4 0.1" />
            </geometry>
        </collision>
        
<inertial>
            <origin rpy="0 0 0" xyz="0 0 0" />
            <mass value="50.0" />
            <inertia ixx="0.70833" ixy="0.0" ixz="0.0" iyy="1.33333" iyz="0.0" izz="0.70833" />
        </inertial>

    </link>
    <gazebo reference="plain_link">
        <meterial>Gazebo/Grey</meterial>
    </gazebo>
    <joint name="base2plain" type="fixed">
        <parent link="base_footprint" />
        <child link="plain_link" />
        <origin rpy="0 0 0" xyz="0 0 0.05" />
    </joint>
    <link name="cylinder_link">
        <visual>
            <geometry>
                <cylinder length="0.6" radius="0.065" />
            </geometry>
            <origin rpy="0 0 0" xyz="0 0 0" />
            <material name="gray">
                <color rgba="0.8 0.8 0.8 1" />
            </material>
        </visual>
        <collision>
            <geometry>
                <cylinder length="0.6" radius="0.065" />
            </geometry>
            <origin rpy="0 0 0" xyz="0 0 0" />
        </collision>
        
<inertial>
            <origin rpy="0 0 0" xyz="0 0 0" />
            <mass value="20.0" />
            <inertia ixx="0.621125" ixy="0.0" ixz="0.0" iyy="0.621125" iyz="0.0" izz="4.225" />
        </inertial>

    </link>
    <gazebo reference="plain_link">
        <meterial>Gazebo/Grey</meterial>
    </gazebo>
    <joint name="plain2cylinder" type="fixed">
        <parent link="plain_link" />
        <child link="cylinder_link" />
        <origin rpy="0 0 0" xyz="0 0 0.35" />
    </joint>
    <link name="Link_0">
        
<inertial>
            <origin rpy="0 0 0" xyz="0 0 0" />
            <mass value="0.46393" />
            <inertia ixx="0.00064494" ixy="-1.0227E-07" ixz="-1.0724E-05" iyy="0.00065157" iyz="3.7859E-07" izz="0.00083278" />
        </inertial>

        <visual>
            <origin rpy="0 0 0" xyz="0.0 0.0 0" />
            <geometry>
                <mesh filename="package://jaka_zu3_myurdf/meshes/Link_0.STL" />
            </geometry>
            <material name="Link_0Color">
                <color rgba="0.84706 0.84706 0.84706 1" />
            </material>
        </visual>
        <collision>
            <origin rpy="0 0 0" xyz="0 0 0" />
            <geometry>
                <mesh filename="package://jaka_zu3_myurdf/meshes/Link_0.STL" />
            </geometry>
        </collision>
    </link>
    <gazebo reference="Link_0">
        <meterial>Gazebo/Grey</meterial>
    </gazebo>
    <joint name="cylinder2base" type="fixed">
        <parent link="cylinder_link" />
        <child link="Link_0" />
        <origin rpy="0 0 0" xyz="0 0 0.3" />
    </joint>
    <link name="Link_1">
        
<inertial>
            <origin rpy="0 0 0" xyz="0 0 0" />
            <mass value="0.88365" />
            <inertia ixx="0.0015634" ixy="1.5495E-08" ixz="5.6443E-09" iyy="0.0015047" iyz="-9.0168E-06" izz="0.0010527" />
        </inertial>

        <visual>
            <origin rpy="0 0 0" xyz="0 0 0" />
            <geometry>
                <mesh filename="package://jaka_zu3_myurdf/meshes/Link_1.STL" />
            </geometry>
            <material name="Link_1Color">
                <color rgba="1 1 1 1" />
            </material>
        </visual>
        <collision>
            <origin rpy="0 0 0" xyz="0 0 0" />
            <geometry>
                <mesh filename="package://jaka_zu3_myurdf/meshes/Link_1.STL" />
            </geometry>
        </collision>
    </link>
    <gazebo reference="Link_1">
        <meterial>Gazebo/Grey</meterial>
    </gazebo>
    <joint name="joint_1" type="revolute">
        <origin rpy="0 0 0" xyz="0 0 0.15055" />
        <parent link="Link_0" />
        <child link="Link_1" />
        <axis xyz="0 0 1" />
        <limit effort="300" lower="-4.71" upper="4.71" velocity="3.14" />
        <dynamics damping="50" friction="1" />
    </joint>
    <transmission name="trans1">
        <type>transmission_interface/SimpleTransmission</type>
        <joint name="joint_1">
            <hardwareInterface>hardware_interface/EffortJointInterface</hardwareInterface>
        </joint>
        <actuator name="motor1">
            <hardwareInterface>hardware_interface/EffortJointInterface</hardwareInterface>
            <mechanicalReduction>1</mechanicalReduction>
        </actuator>
    </transmission>
    <link name="Link_2">
        
<inertial>
            <origin rpy="0 0 0" xyz="0.114 -5.5358E-07 -0.11162" />
            <mass value="2.3202" />
            <inertia ixx="1" ixy="0" ixz="0" iyy="1" iyz="0" izz="1" />
        </inertial>

        <visual>
            <origin rpy="0 0 0" xyz="0 0 0" />
            <geometry>
                <mesh filename="package://jaka_zu3_myurdf/meshes/Link_2.STL" />
            </geometry>
            <material name="Link_2Color">
                <color rgba="1 1 1 1" />
            </material>
        </visual>
        <collision>
            <origin rpy="0 0 0" xyz="0 0 0" />
            <geometry>
                <mesh filename="package://jaka_zu3_myurdf/meshes/Link_2.STL" />
            </geometry>
        </collision>
    </link>
    <gazebo reference="Link_2">
        <meterial>Gazebo/Grey</meterial>
    </gazebo>
    <joint name="joint_2" type="revolute">
        <origin rpy="1.5708 0 0" xyz="0 0 0" />
        <parent link="Link_1" />
        <child link="Link_2" />
        <axis xyz="0 0 1" />
        <limit effort="300" lower="-1.48" upper="4.62" velocity="3.14" />
        <dynamics damping="50" friction="1" />
    </joint>
    <transmission name="trans2">
        <type>transmission_interface/SimpleTransmission</type>
        <joint name="joint_2">
            <hardwareInterface>hardware_interface/EffortJointInterface</hardwareInterface>
        </joint>
        <actuator name="motor2">
            <hardwareInterface>hardware_interface/EffortJointInterface</hardwareInterface>
            <mechanicalReduction>1</mechanicalReduction>
        </actuator>
    </transmission>
    <link name="Link_3">
        
<inertial>
            <origin rpy="0 0 0" xyz="0 0 0" />
            <mass value="1.2034" />
            <inertia ixx="1" ixy="0" ixz="0" iyy="1" iyz="0" izz="1" />
        </inertial>

        <visual>
            <origin rpy="0 0 0" xyz="0 0 0" />
            <geometry>
                <mesh filename="package://jaka_zu3_myurdf/meshes/Link_3.STL" />
            </geometry>
            <material name="Link_3Color">
                <color rgba="1 1 1 1" />
            </material>
        </visual>
        <collision>
            <origin rpy="0 0 0" xyz="0 0 0" />
            <geometry>
                <mesh filename="package://jaka_zu3_myurdf/meshes/Link_3.STL" />
            </geometry>
        </collision>
    </link>
    <gazebo reference="Link_3">
        <meterial>Gazebo/Grey</meterial>
    </gazebo>
    <joint name="joint_3" type="revolute">
        <origin rpy="0 0 0" xyz="0.246 0 0" />
        <parent link="Link_2" />
        <child link="Link_3" />
        <axis xyz="0 0 1" />
        <limit effort="330" lower="-3.05" upper="3.05" velocity="3.14" />
        <dynamics damping="50" friction="1" />
    </joint>
    <transmission name="trans3">
        <type>transmission_interface/SimpleTransmission</type>
        <joint name="joint_3">
            <hardwareInterface>hardware_interface/EffortJointInterface</hardwareInterface>
        </joint>
        <actuator name="motor3">
            <hardwareInterface>hardware_interface/EffortJointInterface</hardwareInterface>
            <mechanicalReduction>1</mechanicalReduction>
        </actuator>
    </transmission>
    <link name="Link_4">
        
<inertial>
            <origin rpy="0 0 0" xyz="6.5395E-08 -0.014051 0.0031609" />
            <mass value="0.49334" />
            <inertia ixx="1" ixy="0" ixz="0" iyy="1" iyz="0" izz="1" />
        </inertial>

        <visual>
            <origin rpy="0 0 0" xyz="0 0 0" />
            <geometry>
                <mesh filename="package://jaka_zu3_myurdf/meshes/Link_4.STL" />
            </geometry>
            <material name="Link_4Color">
                <color rgba="1 1 1 1" />
            </material>
        </visual>
        <collision>
            <origin rpy="0 0 0" xyz="0 0 0" />
            <geometry>
                <mesh filename="package://jaka_zu3_myurdf/meshes/Link_4.STL" />
            </geometry>
        </collision>
    </link>
    <gazebo reference="Link_4">
        <meterial>Gazebo/Grey</meterial>
    </gazebo>
    <joint name="joint_4" type="revolute">
        <origin rpy="0 0 0" xyz="0.228 0 -0.113" />
        <parent link="Link_3" />
        <child link="Link_4" />
        <axis xyz="0 0 1" />
        <limit effort="330" lower="-1.48" upper="4.62" velocity="3.14" />
        <dynamics damping="50" friction="1" />
    </joint>
    <transmission name="trans4">
        <type>transmission_interface/SimpleTransmission</type>
        <joint name="joint_4">
            <hardwareInterface>hardware_interface/EffortJointInterface</hardwareInterface>
        </joint>
        <actuator name="motor4">
            <hardwareInterface>hardware_interface/EffortJointInterface</hardwareInterface>
            <mechanicalReduction>1</mechanicalReduction>
        </actuator>
    </transmission>
    <link name="Link_5">
        
<inertial>
            <origin rpy="0 0 0" xyz="2.5684E-07 0.0068642 -0.0021581" />
            <mass value="0.55082" />
            <inertia ixx="1" ixy="0" ixz="0" iyy="1" iyz="0" izz="1" />
        </inertial>

        <visual>
            <origin rpy="0 0 0" xyz="0 0 0" />
            <geometry>
                <mesh filename="package://jaka_zu3_myurdf/meshes/Link_5.STL" />
            </geometry>
            <material name="Link_5Color">
                <color rgba="1 1 1 1" />
            </material>
        </visual>
        <collision>
            <origin rpy="0 0 0" xyz="0 0 0" />
            <geometry>
                <mesh filename="package://jaka_zu3_myurdf/meshes/Link_5.STL" />
            </geometry>
        </collision>
    </link>
    <gazebo reference="Link_5">
        <meterial>Gazebo/Grey</meterial>
    </gazebo>
    <joint name="joint_5" type="revolute">
        <origin rpy="1.5708 0 0" xyz="0 -0.11675 0" />
        <parent link="Link_4" />
        <child link="Link_5" />
        <axis xyz="0 0 1" />
        <limit effort="330" lower="-4.71" upper="4.71" velocity="3.83" />
        <dynamics damping="50" friction="1" />
    </joint>
    <transmission name="trans5">
        <type>transmission_interface/SimpleTransmission</type>
        <joint name="joint_5">
            <hardwareInterface>hardware_interface/EffortJointInterface</hardwareInterface>
        </joint>
        <actuator name="motor5">
            <hardwareInterface>hardware_interface/EffortJointInterface</hardwareInterface>
            <mechanicalReduction>1</mechanicalReduction>
        </actuator>
    </transmission>
    <link name="Link_6">
        
<inertial>
            <origin rpy="0 0 0" xyz="5.2572E-05 -0.0001007 -0.0091035" />
            <mass value="0.094884" />
            <inertia ixx="1" ixy="0" ixz="0" iyy="1" iyz="0" izz="1" />
        </inertial>

        <visual>
            <origin rpy="0 0 0" xyz="0 0 0" />
            <geometry>
                <mesh filename="package://jaka_zu3_myurdf/meshes/Link_6.STL" />
            </geometry>
            <material name="Link_6Color">
                <color rgba="1 1 1 1" />
            </material>
        </visual>
        <collision>
            <origin rpy="0 0 0" xyz="0 0 0" />
            <geometry>
                <mesh filename="package://jaka_zu3_myurdf/meshes/Link_6.STL" />
            </geometry>
        </collision>
    </link>
    <gazebo reference="Link_6">
        <meterial>Gazebo/Grey</meterial>
    </gazebo>
    <joint name="joint_6" type="revolute">
        <origin rpy="-1.5708 0 0" xyz="0 0.0985 0" />
        <parent link="Link_5" />
        <child link="Link_6" />
        <axis xyz="0 0 -1" />
        <limit effort="330" lower="-6.283185" upper="6.283185" velocity="3.14" />
        <dynamics damping="50" friction="1" />
    </joint>
    <transmission name="trans6">
        <type>transmission_interface/SimpleTransmission</type>
        <joint name="joint_6">
            <hardwareInterface>hardware_interface/EffortJointInterface</hardwareInterface>
        </joint>
        <actuator name="motor6">
            <hardwareInterface>hardware_interface/EffortJointInterface</hardwareInterface>
            <mechanicalReduction>1</mechanicalReduction>
        </actuator>
    </transmission>
    <transmission name="trans_joint_1">
        <type>transmission_interface/SimpleTransmission</type>
        <joint name="joint_1">
            <hardwareInterface>hardware_interface/EffortJointInterface</hardwareInterface>
        </joint>
        <actuator name="joint_1_motor">
            <hardwareInterface>hardware_interface/EffortJointInterface</hardwareInterface>
            <mechanicalReduction>1</mechanicalReduction>
        </actuator>
    </transmission>
    <transmission name="trans_joint_2">
        <type>transmission_interface/SimpleTransmission</type>
        <joint name="joint_2">
            <hardwareInterface>hardware_interface/EffortJointInterface</hardwareInterface>
        </joint>
        <actuator name="joint_2_motor">
            <hardwareInterface>hardware_interface/EffortJointInterface</hardwareInterface>
            <mechanicalReduction>1</mechanicalReduction>
        </actuator>
    </transmission>
    <transmission name="trans_joint_3">
        <type>transmission_interface/SimpleTransmission</type>
        <joint name="joint_3">
            <hardwareInterface>hardware_interface/EffortJointInterface</hardwareInterface>
        </joint>
        <actuator name="joint_3_motor">
            <hardwareInterface>hardware_interface/EffortJointInterface</hardwareInterface>
            <mechanicalReduction>1</mechanicalReduction>
        </actuator>
    </transmission>
    <transmission name="trans_joint_4">
        <type>transmission_interface/SimpleTransmission</type>
        <joint name="joint_4">
            <hardwareInterface>hardware_interface/EffortJointInterface</hardwareInterface>
        </joint>
        <actuator name="joint_4_motor">
            <hardwareInterface>hardware_interface/EffortJointInterface</hardwareInterface>
            <mechanicalReduction>1</mechanicalReduction>
        </actuator>
    </transmission>
    <transmission name="trans_joint_5">
        <type>transmission_interface/SimpleTransmission</type>
        <joint name="joint_5">
            <hardwareInterface>hardware_interface/EffortJointInterface</hardwareInterface>
        </joint>
        <actuator name="joint_5_motor">
            <hardwareInterface>hardware_interface/EffortJointInterface</hardwareInterface>
            <mechanicalReduction>1</mechanicalReduction>
        </actuator>
    </transmission>
    <transmission name="trans_joint_6">
        <type>transmission_interface/SimpleTransmission</type>
        <joint name="joint_6">
            <hardwareInterface>hardware_interface/EffortJointInterface</hardwareInterface>
        </joint>
        <actuator name="joint_6_motor">
            <hardwareInterface>hardware_interface/EffortJointInterface</hardwareInterface>
            <mechanicalReduction>1</mechanicalReduction>
        </actuator>
    </transmission>
    <gazebo>
        <plugin name="gazebo_ros_control" filename="libgazebo_ros_control.so">
            <robotNamespace>/</robotNamespace>
        </plugin>
    </gazebo>
</robot>

<transmission name="trans1">
        <type>transmission_interface/SimpleTransmission</type>
        <joint name="joint_1">
            <hardwareInterface>hardware_interface/EffortJointInterface</hardwareInterface>
        </joint>
        <actuator name="motor1">
            <hardwareInterface>hardware_interface/EffortJointInterface</hardwareInterface>
            <mechanicalReduction>1</mechanicalReduction>
        </actuator>
    </transmission>
    <link name="Link_2">
        <inertial>
            <origin rpy="0 0 0" xyz="0.114 -5.5358E-07 -0.11162" />
            <mass value="2.3202" />
            <inertia ixx="1" ixy="0" ixz="0" iyy="1" iyz="0" izz="1" />
        </inertial>
        <visual>
            <origin rpy="0 0 0" xyz="0 0 0" />
            <geometry>
                <mesh filename="package://jaka_zu3_myurdf/meshes/Link_2.STL" />
            </geometry>
            <material name="Link_2Color">
                <color rgba="1 1 1 1" />
            </material>
        </visual>
        <collision>
            <origin rpy="0 0 0" xyz="0 0 0" />
            <geometry>
                <mesh filename="package://jaka_zu3_myurdf/meshes/Link_2.STL" />
            </geometry>
        </collision>
    </link>
    <gazebo reference="Link_2">
        <meterial>Gazebo/Grey</meterial>
    </gazebo>
    <joint name="joint_2" type="revolute">
        <origin rpy="1.5708 0 0" xyz="0 0 0" />
        <parent link="Link_1" />
        <child link="Link_2" />
        <axis xyz="0 0 1" />
        <limit effort="300" lower="-1.48" upper="4.62" velocity="3.14" />
        <dynamics damping="50" friction="1" />
    </joint>
    <transmission name="trans2">
        <type>transmission_interface/SimpleTransmission</type>
        <joint name="joint_2">
            <hardwareInterface>hardware_interface/EffortJointInterface</hardwareInterface>
        </joint>
        <actuator name="motor2">
            <hardwareInterface>hardware_interface/EffortJointInterface</hardwareInterface>
            <mechanicalReduction>1</mechanicalReduction>
        </actuator>
    </transmission>
    <link name="Link_3">
        <inertial>
            <origin rpy="0 0 0" xyz="0 0 0" />
            <mass value="1.2034" />
            <inertia ixx="1" ixy="0" ixz="0" iyy="1" iyz="0" izz="1" />
        </inertial>
        <visual>
            <origin rpy="0 0 0" xyz="0 0 0" />
            <geometry>
                <mesh filename="package://jaka_zu3_myurdf/meshes/Link_3.STL" />
            </geometry>
            <material name="Link_3Color">
                <color rgba="1 1 1 1" />
            </material>
        </visual>
        <collision>
            <origin rpy="0 0 0" xyz="0 0 0" />
            <geometry>
                <mesh filename="package://jaka_zu3_myurdf/meshes/Link_3.STL" />
            </geometry>
        </collision>
    </link>
    <gazebo reference="Link_3">
        <meterial>Gazebo/Grey</meterial>
    </gazebo>
    <joint name="joint_3" type="revolute">
        <origin rpy="0 0 0" xyz="0.246 0 0" />
        <parent link="Link_2" />
        <child link="Link_3" />
        <axis xyz="0 0 1" />
        <limit effort="330" lower="-3.05" upper="3.05" velocity="3.14" />
        <dynamics damping="50" friction="1" />
    </joint>
    <transmission name="trans3">
        <type>transmission_interface/SimpleTransmission</type>
        <joint name="joint_3">
            <hardwareInterface>hardware_interface/EffortJointInterface</hardwareInterface>
        </joint>
        <actuator name="motor3">
            <hardwareInterface>hardware_interface/EffortJointInterface</hardwareInterface>
            <mechanicalReduction>1</mechanicalReduction>
        </actuator>
    </transmission>
    <link name="Link_4">
        <inertial>
            <origin rpy="0 0 0" xyz="6.5395E-08 -0.014051 0.0031609" />
            <mass value="0.49334" />
            <inertia ixx="1" ixy="0" ixz="0" iyy="1" iyz="0" izz="1" />
        </inertial>
        <visual>
            <origin rpy="0 0 0" xyz="0 0 0" />
            <geometry>
                <mesh filename="package://jaka_zu3_myurdf/meshes/Link_4.STL" />
            </geometry>
            <material name="Link_4Color">
                <color rgba="1 1 1 1" />
            </material>
        </visual>
        <collision>
            <origin rpy="0 0 0" xyz="0 0 0" />
            <geometry>
                <mesh filename="package://jaka_zu3_myurdf/meshes/Link_4.STL" />
            </geometry>
        </collision>
    </link>
    <gazebo reference="Link_4">
        <meterial>Gazebo/Grey</meterial>
    </gazebo>
    <joint name="joint_4" type="revolute">
        <origin rpy="0 0 0" xyz="0.228 0 -0.113" />
        <parent link="Link_3" />
        <child link="Link_4" />
        <axis xyz="0 0 1" />
        <limit effort="330" lower="-1.48" upper="4.62" velocity="3.14" />
        <dynamics damping="50" friction="1" />
    </joint>
    <transmission name="trans4">
        <type>transmission_interface/SimpleTransmission</type>
        <joint name="joint_4">
            <hardwareInterface>hardware_interface/EffortJointInterface</hardwareInterface>
        </joint>
        <actuator name="motor4">
            <hardwareInterface>hardware_interface/EffortJointInterface</hardwareInterface>
            <mechanicalReduction>1</mechanicalReduction>
        </actuator>
    </transmission>
    <link name="Link_5">
        <inertial>
            <origin rpy="0 0 0" xyz="2.5684E-07 0.0068642 -0.0021581" />
            <mass value="0.55082" />
            <inertia ixx="1" ixy="0" ixz="0" iyy="1" iyz="0" izz="1" />
        </inertial>
        <visual>
            <origin rpy="0 0 0" xyz="0 0 0" />
            <geometry>
                <mesh filename="package://jaka_zu3_myurdf/meshes/Link_5.STL" />
            </geometry>
            <material name="Link_5Color">
                <color rgba="1 1 1 1" />
            </material>
        </visual>
        <collision>
            <origin rpy="0 0 0" xyz="0 0 0" />
            <geometry>
                <mesh filename="package://jaka_zu3_myurdf/meshes/Link_5.STL" />
            </geometry>
        </collision>
    </link>
    <gazebo reference="Link_5">
        <meterial>Gazebo/Grey</meterial>
    </gazebo>
    <joint name="joint_5" type="revolute">
        <origin rpy="1.5708 0 0" xyz="0 -0.11675 0" />
        <parent link="Link_4" />
        <child link="Link_5" />
        <axis xyz="0 0 1" />
        <limit effort="330" lower="-4.71" upper="4.71" velocity="3.83" />
        <dynamics damping="50" friction="1" />
    </joint>
    <transmission name="trans5">
        <type>transmission_interface/SimpleTransmission</type>
        <joint name="joint_5">
            <hardwareInterface>hardware_interface/EffortJointInterface</hardwareInterface>
        </joint>
        <actuator name="motor5">
            <hardwareInterface>hardware_interface/EffortJointInterface</hardwareInterface>
            <mechanicalReduction>1</mechanicalReduction>
        </actuator>
    </transmission>
    <link name="Link_6">
        <inertial>
            <origin rpy="0 0 0" xyz="5.2572E-05 -0.0001007 -0.0091035" />
            <mass value="0.094884" />
            <inertia ixx="1" ixy="0" ixz="0" iyy="1" iyz="0" izz="1" />
        </inertial>
        <visual>
            <origin rpy="0 0 0" xyz="0 0 0" />
            <geometry>
                <mesh filename="package://jaka_zu3_myurdf/meshes/Link_6.STL" />
            </geometry>
            <material name="Link_6Color">
                <color rgba="1 1 1 1" />
            </material>
        </visual>
        <collision>
            <origin rpy="0 0 0" xyz="0 0 0" />
            <geometry>
                <mesh filename="package://jaka_zu3_myurdf/meshes/Link_6.STL" />
            </geometry>
        </collision>
    </link>
    <gazebo reference="Link_6">
        <meterial>Gazebo/Grey</meterial>
    </gazebo>
    <joint name="joint_6" type="revolute">
        <origin rpy="-1.5708 0 0" xyz="0 0.0985 0" />
        <parent link="Link_5" />
        <child link="Link_6" />
        <axis xyz="0 0 -1" />
        <limit effort="330" lower="-6.283185" upper="6.283185" velocity="3.14" />
        <dynamics damping="50" friction="1" />
    </joint>
    <transmission name="trans6">
        <type>transmission_interface/SimpleTransmission</type>
        <joint name="joint_6">
            <hardwareInterface>hardware_interface/EffortJointInterface</hardwareInterface>
        </joint>
        <actuator name="motor6">
            <hardwareInterface>hardware_interface/EffortJointInterface</hardwareInterface>
            <mechanicalReduction>1</mechanicalReduction>
        </actuator>
    </transmission>
    <transmission name="trans_joint_1">
        <type>transmission_interface/SimpleTransmission</type>
        <joint name="joint_1">
            <hardwareInterface>hardware_interface/EffortJointInterface</hardwareInterface>
        </joint>
        <actuator name="joint_1_motor">
            <hardwareInterface>hardware_interface/EffortJointInterface</hardwareInterface>
            <mechanicalReduction>1</mechanicalReduction>
        </actuator>
    </transmission>
    <transmission name="trans_joint_2">
        <type>transmission_interface/SimpleTransmission</type>
        <joint name="joint_2">
            <hardwareInterface>hardware_interface/EffortJointInterface</hardwareInterface>
        </joint>
        <actuator name="joint_2_motor">
            <hardwareInterface>hardware_interface/EffortJointInterface</hardwareInterface>
            <mechanicalReduction>1</mechanicalReduction>
        </actuator>
    </transmission>
    <transmission name="trans_joint_3">
        <type>transmission_interface/SimpleTransmission</type>
        <joint name="joint_3">
            <hardwareInterface>hardware_interface/EffortJointInterface</hardwareInterface>
        </joint>
        <actuator name="joint_3_motor">
            <hardwareInterface>hardware_interface/EffortJointInterface</hardwareInterface>
            <mechanicalReduction>1</mechanicalReduction>
        </actuator>
    </transmission>
    <transmission name="trans_joint_4">
        <type>transmission_interface/SimpleTransmission</type>
        <joint name="joint_4">
            <hardwareInterface>hardware_interface/EffortJointInterface</hardwareInterface>
        </joint>
        <actuator name="joint_4_motor">
            <hardwareInterface>hardware_interface/EffortJointInterface</hardwareInterface>
            <mechanicalReduction>1</mechanicalReduction>
        </actuator>
    </transmission>
    <transmission name="trans_joint_5">
        <type>transmission_interface/SimpleTransmission</type>
        <joint name="joint_5">
            <hardwareInterface>hardware_interface/EffortJointInterface</hardwareInterface>
        </joint>
        <actuator name="joint_5_motor">
            <hardwareInterface>hardware_interface/EffortJointInterface</hardwareInterface>
            <mechanicalReduction>1</mechanicalReduction>
        </actuator>
    </transmission>
    <transmission name="trans_joint_6">
        <type>transmission_interface/SimpleTransmission</type>
        <joint name="joint_6">
            <hardwareInterface>hardware_interface/EffortJointInterface</hardwareInterface>
        </joint>
        <actuator name="joint_6_motor">
            <hardwareInterface>hardware_interface/EffortJointInterface</hardwareInterface>
            <mechanicalReduction>1</mechanicalReduction>
        </actuator>
    </transmission>
    <gazebo>
        <plugin name="gazebo_ros_control" filename="libgazebo_ros_control.so">
            <robotNamespace>/</robotNamespace>
        </plugin>
    </gazebo>
</robot>
