<?xml version="1.0" encoding="utf-8"?>
<!-- This URDF was automatically created by SolidWorks to URDF Exporter! Originally created by Stephen Brawner (brawner@gmail.com) 
     Commit Version: 1.6.0-1-g15f4949  Build Version: 1.6.7594.29634
     For more information, please see http://wiki.ros.org/sw_urdf_exporter -->
<robot name="jaka_zu3">
  <link name="base_footprint">
    <visual>
      <geometry>
        <sphere radius="0.001" />
      </geometry>
      <oringin xyz="0 0 0" rpy="0 0 0" />
    </visual>
  </link>
  
  <link name="plain_link" >
    <visual>
      <origin xyz="0 0 0" rpy="0 0 0" />
      <geometry>
        <box size="0.4 0.4 0.1" />
        <origin xyz="0 0 0" rpy="0 0 0" />
      </geometry>
      <material
        name="plaincolor">
        <color rgba="0.84706 0.84706 0.84706 1" />
      </material>
    </visual>
    <collision>
      <origin xyz="0 0 0" rpy="0 0 0" />
      <geometry>
        <box size="0.4 0.4 0.1" />
      </geometry>
    </collision>
    <inertial>
      <origin xyz="0 0 0" rpy="0 0 0" />
      <mass value="50.0" />
      <inertia ixx="0.70833" ixy="0.0" ixz="0.0" 
               iyy="1.33333" iyz="0.0" izz="0.70833" />
    </inertial>
  </link>

  <joint name="base2plain" type="fixed">
    <parent link="base_footprint" />
    <child link="plain_link" />
    <origin xyz="0 0 0.05" rpy="0 0 0" />
  </joint>


  <link name="cylinder_link">
    <visual>
      <geometry>
        <cylinder radius="0.065" length="0.6" /> 
      </geometry>
      <origin xyz="0 0 0" rpy="0 0 0" />
      <material name="gray">
        <color rgba="0.8 0.8 0.8 1" />
      </material>
    </visual>
    <collision>
      <geometry>
        <cylinder radius="0.065" length="0.6" />
      </geometry>
      <origin xyz="0 0 0" rpy="0 0 0" />
    </collision>
    <inertial>
      <origin xyz="0 0 0" rpy="0 0 0" />
      <mass value="20.0" />
      <inertia ixx="0.621125" ixy="0.0" ixz="0.0" 
               iyy="0.621125" iyz="0.0" izz="4.225" />
    </inertial>
  </link> 

  <joint name="plain2cylinder" type="fixed">
    <parent link="plain_link" />
    <child link="cylinder_link" />
    <origin xyz="0 0 0.35" rpy="0 0 0" />
  </joint>

  <link name="Link_0">
    <inertial>
      <origin
          xyz="0 0 0"
          rpy="0 0 0" />
      <mass
          value="0.46393" />
      <inertia
          ixx="0.00064494"
          ixy="-1.0227E-07"
          ixz="-1.0724E-05"
          iyy="0.00065157"
          iyz="3.7859E-07"
          izz="0.00083278" />
    </inertial>
    <visual>
      <origin xyz="0.0 0.0 0" rpy="0 0 0" />
      <geometry>
        <mesh filename="package://jaka_zu3_myurdf/meshes/Link_0.STL" />
      </geometry>
      <material
        name="Link_0Color">
        <color
          rgba="0.84706 0.84706 0.84706 1" />
      </material>
    </visual>
    <collision>
      <origin xyz="0 0 0" rpy="0 0 0" />
      <geometry>
        <mesh filename="package://jaka_zu3_myurdf/meshes/Link_0.STL" />
      </geometry>
    </collision>
  </link>

  <joint name="cylinder2base" type="fixed">
    <parent link="cylinder_link" />
    <child link="Link_0" />
    <origin xyz="0 0 0.3" rpy="0 0 0" />
  </joint>

  <link name="Link_1">
    <inertial>
        <origin
          xyz="0 0 0"
          rpy="0 0 0" />
        <mass
          value="0.88365" />
        <inertia
          ixx="0.0015634"
          ixy="1.5495E-08"
          ixz="5.6443E-09"
          iyy="0.0015047"
          iyz="-9.0168E-06"
          izz="0.0010527" />
      </inertial>
    
    <visual>
      <origin xyz="0 0 0" rpy="0 0 0" />
      <geometry>
        <mesh filename="package://jaka_zu3_myurdf/meshes/Link_1.STL" />
      </geometry>
      <material
        name="Link_1Color">
        <color
          rgba="1 1 1 1" />
      </material>
    </visual>
    <collision>
      <origin xyz="0 0 0" rpy="0 0 0" />
      <geometry>
        <mesh filename="package://jaka_zu3_myurdf/meshes/Link_1.STL" />
      </geometry>
    </collision>
  </link>

  <joint name="joint_1" type="revolute">
    <origin xyz="0 0 0.15055" rpy="0 0 0" />
    <parent link="Link_0" />
    <child link="Link_1" />
    <axis xyz="0 0 1" />
    <limit
      lower="-4.71"
      upper="4.71"
      effort="300"
      velocity="3.14" />
    <dynamics
      damping="50"
      friction="1" />
  </joint>

  <link name="Link_2">
    <inertial>
        <origin
          xyz="0.114 -5.5358E-07 -0.11162"
          rpy="0 0 0" />
        <mass
          value="2.3202" />
        <inertia
          ixx="0.0032518"
          ixy="1.6898E-08"
          ixz="-3.3843E-06"
          iyy="0.0045664"
          iyz="9.1919E-09"
          izz="0.0035107" />
      </inertial>
    <visual>
      <origin xyz="0 0 0" rpy="0 0 0" />
      <geometry>
        <mesh filename="package://jaka_zu3_myurdf/meshes/Link_2.STL" />
      </geometry>
      <material
        name="Link_2Color">
        <color
          rgba="1 1 1 1" />
      </material>
    </visual>
    <collision>
      <origin xyz="0 0 0" rpy="0 0 0" />
      <geometry>
        <mesh filename="package://jaka_zu3_myurdf/meshes/Link_2.STL" />
      </geometry>
    </collision>
  </link>

  <joint name="joint_2" type="revolute">
    <origin xyz="0 0 0" rpy="1.5708 0 0" />
    <parent link="Link_1" />
    <child link="Link_2" />
    <axis xyz="0 0 1" />
    <limit
      lower="-1.48"
      upper="4.62"
      effort="300"
      velocity="3.14" />
    <dynamics
      damping="50"
      friction="1" />
  </joint>

  <link name="Link_3">
    <inertial>
        <origin
          xyz="0 0 0"
          rpy="0 0 0" />
        <mass
          value="1.2034" />
        <inertia
          ixx="0.00093819"
          ixy="1.276E-07"
          ixz="-0.00033673"
          iyy="0.0038664"
          iyz="5.3811E-08"
          izz="0.0036229" />
      </inertial>
    
    <visual>
      <origin xyz="0 0 0" rpy="0 0 0" />
      <geometry>
        <mesh filename="package://jaka_zu3_myurdf/meshes/Link_3.STL" />
      </geometry>
      <material
        name="Link_3Color">
        <color
          rgba="1 1 1 1" />
      </material>
    </visual>
    <collision>
      <origin xyz="0 0 0" rpy="0 0 0" />
      <geometry>
        <mesh filename="package://jaka_zu3_myurdf/meshes/Link_3.STL" />
      </geometry>
    </collision>
  </link>

  <joint name="joint_3" type="revolute">
    <origin xyz="0.246 0 0" rpy="0 0 0" />
    <parent link="Link_2" />
    <child link="Link_3" />
    <axis xyz="0 0 1" />
    <limit lower="-3.05" upper="3.05" effort="330" velocity="3.14" />
    <dynamics damping="50" friction="1" />
  </joint>

  <link name="Link_4">
    <inertial>
        <origin
          xyz="6.5395E-08 -0.014051 0.0031609"
          rpy="0 0 0" />
        <mass
          value="0.49334" />
        <inertia
          ixx="0.00050163"
          ixy="-3.5155E-09"
          ixz="-2.6858E-09"
          iyy="0.00032415"
          iyz="-6.2159E-05"
          izz="0.00047909" />
      </inertial>
    
    <visual>
      <origin xyz="0 0 0" rpy="0 0 0" />
      <geometry>
        <mesh filename="package://jaka_zu3_myurdf/meshes/Link_4.STL" />
      </geometry>
      <material
        name="Link_4Color">
        <color
          rgba="1 1 1 1" />
      </material>
    </visual>
    <collision>
      <origin xyz="0 0 0" rpy="0 0 0" />
      <geometry>
        <mesh filename="package://jaka_zu3_myurdf/meshes/Link_4.STL" />
      </geometry>
    </collision>
  </link>
  <gazebo reference="Link_4">
    <meterial>Gazebo/Grey</meterial>
  </gazebo>

  <joint name="joint_4" type="revolute">
    <origin xyz="0.228 0 -0.113" rpy="0 0 0" />
    <parent link="Link_3" />
    <child link="Link_4" />
    <axis xyz="0 0 1" />
    <limit lower="-1.48" upper="4.62" effort="330" velocity="3.14" />
    <dynamics damping="50" friction="1" />
  </joint>

  <link name="Link_5">
    <inertial>
        <origin
          xyz="2.5684E-07 0.0068642 -0.0021581"
          rpy="0 0 0" />
        <mass
          value="0.55082" />
        <inertia
          ixx="0.0010014"
          ixy="4.8947E-09"
          ixz="4.7274E-10"
          iyy="0.00036028"
          iyz="-1.6847E-05"
          izz="0.0009728" />
      </inertial>
    
    <visual>
      <origin xyz="0 0 0" rpy="0 0 0" />
      <geometry>
        <mesh filename="package://jaka_zu3_myurdf/meshes/Link_5.STL" />
      </geometry>
      <material
        name="Link_5Color">
        <color
          rgba="1 1 1 1" />
      </material>
    </visual>
    <collision>
      <origin xyz="0 0 0" rpy="0 0 0" />
      <geometry>
        <mesh filename="package://jaka_zu3_myurdf/meshes/Link_5.STL" />
      </geometry>
    </collision>
  </link>
  <gazebo reference="Link_5">
    <meterial>Gazebo/Grey</meterial>
  </gazebo>

  <joint name="joint_5" type="revolute">
    <origin xyz="0 -0.11675 0" rpy="1.5708 0 0" />
    <parent link="Link_4" />
    <child link="Link_5" />
    <axis xyz="0 0 1" />
    <limit lower="-4.71" upper="4.71" effort="330" velocity="3.83" />
    <dynamics damping="50" friction="1" />
  </joint>

  <link name="Link_6">
    <inertial>
        <origin
          xyz="5.2572E-05 -0.0001007 -0.0091035"
          rpy="0 0 0" />
        <mass
          value="0.094884" />
        <inertia
          ixx="3.2886E-05"
          ixy="-8.8218E-08"
          ixz="-5.2215E-08"
          iyy="3.3701E-05"
          iyz="2.9383E-07"
          izz="5.458E-05" />
      </inertial>
    
    <visual>
      <origin xyz="0 0 0" rpy="0 0 0" />
      <geometry>
        <mesh filename="package://jaka_zu3_myurdf/meshes/Link_6.STL" />
      </geometry>
      <material
        name="Link_6Color">
        <color
          rgba="1 1 1 1" />
      </material>
    </visual>
    <collision>
      <origin xyz="0 0 0" rpy="0 0 0" />
      <geometry>
        <mesh filename="package://jaka_zu3_myurdf/meshes/Link_6.STL" />
      </geometry>
    </collision>
  </link>
  <gazebo reference="Link_6">
    <meterial>Gazebo/Grey</meterial>
  </gazebo>


  <joint name="joint_6" type="revolute">
    <origin
      xyz="0 0.0985 0"
      rpy="-1.5708 0 0" />
    <parent link="Link_5" />
    <child link="Link_6" />
    <axis xyz="0 0 -1" />
    <limit lower="-6.283185" upper="6.283185" effort="330" velocity="3.14" />
    <dynamics damping="50" friction="1" />
  </joint>
  

</robot>