<?xml version="1.0" encoding="utf-8" ?>

<robot name="jaka_zu3" xmlns:xacro="http://www.ros.org/wiki/xacro">
  <xacro:include filename="gazebo_control.xacro" />
  <xacro:include filename="camera.xacro" />

  <xacro:macro name="cylinder_inertial" params="radius length mass">
    <inertial>
      <mass value="${mass}" />
      <inertia ixx="${mass * (3 * radius * radius + length * length) / 12}" ixy="0.0" ixz="0.0"
        iyy="${mass * (3 * radius * radius + length * length) / 12}" iyz="0.0"
        izz="${0.5 * mass * radius * radius}" />
    </inertial>
  </xacro:macro>

  <xacro:macro name="box_inertial" params="l w h mass ">
    <inertial>
      <mass value="${mass}" />
      <inertia ixx="${mass * (h * h + l * l) / 12}" ixy="0.0" ixz="0.0"
        iyy="${mass * (w * w + l * l) / 12}" iyz="0.0"
        izz="${mass * (w * w + h * h) / 12}" />
    </inertial>
  </xacro:macro>
  
  <xacro:property name="pi" value="3.1415926" />
  <xacro:property name="base_mass" value="2.0" />  <!-- 0.464  Ixx = 1845.903	Ixy = -26.271	Ixz = -0.086 Iyx = -26.271	Iyy = 833.895	Iyz = -0.041 Izx = -0.086	Izy = -0.041	Izz = 1853.667-->    
  <xacro:property name="link1_mass" value="2.0" />  <!--0.897  Ixx = 4871.776	Ixy = 228.402	Ixz = 0.020 Iyx = 228.402	Iyy = 1103.322	Iyz = 0.011 Izx = 0.020	Izy = 0.011	Izz = 4967.703 -->
  <xacro:property name="link2_mass" value="3.42" /> <!--2.325 Ixx = 12015.974	Ixy = 16132.791	Ixz = 0.020 Iyx = 16132.791	Iyy = 57075.725	Iyz = 0.006 Izx = 0.020	Izy = 0.006	Izz = 66888.516 -->
  <xacro:property name="link3_mass" value="3.42" /> <!--1.213 Ixx = 1312.921	Ixy = -0.156	Ixz = 1247.110 Iyx = -0.156	Iyy = 22571.408	Iyz = -0.011 Izx = 1247.110	Izy = -0.011	Izz = 21960.918 -->
  <xacro:property name="link4_mass" value="0.8" /> <!--0.493 Ixx = 2610.725	Ixy = 121.849	Ixz = 0.001 Iyx = 121.849	Iyy = 334.757	Iyz = 0.001 Izx = 0.001	Izy = 0.001	Izz = 2643.893 -->
  <xacro:property name="link5_mass" value="0.8" /> <!--0.551 Ixx = 3611.091	Ixy = 98.862	Ixz = 0.004 Iyx = 98.862	Iyy = 362.851	Iyz = 0.003 Izx = 0.004	Izy = 0.003	Izz = 3642.214 -->
  <xacro:property name="link6_mass" value="0.35" /> <!--0.1 Ixx = 63.206	Ixy = -0.028	Ixz = -0.089 Iyx = -0.028	Iyy = 58.133	Iyz = 0.025 Izx = -0.089	Izy = 0.025	Izz = 62.796 -->


  <xacro:property name="joint_1_lower_limit" value="-4.71" />
  <xacro:property name="joint_1_upper_limit" value="4.71" />

  <xacro:property name="joint_2_lower_limit" value="-1.48" />
  <xacro:property name="joint_2_upper_limit" value="4.62" />

  <xacro:property name="joint_3_lower_limit" value="-3.05" />
  <xacro:property name="joint_3_upper_limit" value="3.05" />

  <xacro:property name="joint_4_lower_limit" value="-1.48" />
  <xacro:property name="joint_4_upper_limit" value="4.62" />

  <xacro:property name="joint_5_lower_limit" value="-4.71" />
  <xacro:property name="joint_5_upper_limit" value="4.71" />

  <xacro:property name="joint_6_lower_limit" value="${-2 * pi}" />
  <xacro:property name="joint_6_upper_limit" value="${2 * pi}" />

  <xacro:property name="safety_pos_margin" value="0.15" />
  <xacro:property name="safety_k_position" value="20" />

  <link name="plain_link">
    <visual>
      <geometry>
        <box size="0.4 0.4 0.1" /> 
      </geometry>
      <origin xyz="0 0 0" rpy="0 0 0" />
      <material name="gray">
        <color rgba="0.8 0.8 0.8 1" />
      </material>
    </visual>
    <collision>
      <geometry>
        <box size="0.4 0.4 0.1" />
      </geometry>
      <origin xyz="0 0 0" rpy="0 0 0" />
    </collision>
    <xacro:box_inertial mass="200.0" l="1" w="1" h="0.2" />
  </link>
  <gazebo reference="plain_link">
    <!-- <selfCollide>true</selfCollide> -->
    <meterial>Gazebo/Grey</meterial>
  </gazebo>

  <joint name="plain2cylinder" type="fixed">
    <parent link="plain_link" />
    <child link="cylinder_link" />
    <origin xyz="0 0 0.35" rpy="0 0 0" />
  </joint>

  <link name="cylinder_link">
    <visual>
      <geometry>
        <cylinder radius="0.065" length="0.6" /> 
      </geometry>
      <origin xyz="0 0 0" rpy="0 0 0" />
      <material name="gray">
        <color rgba="0.8 0.8 0.8 1" />
      </material>
    </visual>
    <collision>
      <geometry>
        <cylinder radius="0.065" length="0.6" />
      </geometry>
      <origin xyz="0 0 0" rpy="0 0 0" />
    </collision>
    <!-- <inertial>
      <origin xyz="0 0 0" rpy="0 0 0" />
      <mass value="20.0" />
      <inertia ixx="1" ixy="0" ixz="0" iyy="0.9875" iyz="0" izz="1" />
    </inertial> -->
    <xacro:cylinder_inertial mass="20.0" radius="0.065" length="0.6" />
  </link>
  <gazebo reference="cylinder_link">
    <!-- <selfCollide>true</selfCollide> -->
    <meterial>Gazebo/Grey</meterial>
  </gazebo>

  <joint name="cylinder2base" type="fixed">
    <parent link="cylinder_link" />
    <child link="Link_0" />
    <origin xyz="0 0 0.3" rpy="0 0 0" />
  </joint>


  <link name="Link_0">
    <inertial>
      <origin
          xyz="0 0 0"
          rpy="0 0 0" />
      <mass
          value="0.46393" />
      <inertia
          ixx="0.00064494"
          ixy="-1.0227E-07"
          ixz="-1.0724E-05"
          iyy="0.00065157"
          iyz="3.7859E-07"
          izz="0.00083278" />
    </inertial>
    <visual>
      <origin xyz="0.0 0.0 0" rpy="0 0 0" />
      <geometry>
        <mesh filename="package://jaka_zu3_myurdf/meshes/Link_0.STL" />
      </geometry>
      <material
        name="Link_0Color">
        <color
          rgba="0.84706 0.84706 0.84706 1" />
      </material>
    </visual>
    <collision>
      <origin xyz="0 0 0" rpy="0 0 0" />
      <geometry>
        <mesh filename="package://jaka_zu3_myurdf/meshes/Link_0.STL" />
      </geometry>
    </collision>
    <!-- <xacro:cylinder_inertial radius="0.04" length="0.075" mass="${base_mass}" /> -->
  </link>
  <gazebo reference="Link_0">
    <!-- <selfCollide>true</selfCollide> -->
    <meterial>Gazebo/Grey</meterial>
  </gazebo>

  <link name="Link_1">
    <inertial>
        <origin
          xyz="0 0 0"
          rpy="0 0 0" />
        <mass
          value="0.88365" />
        <inertia
          ixx="0.0015634"
          ixy="1.5495E-08"
          ixz="5.6443E-09"
          iyy="0.0015047"
          iyz="-9.0168E-06"
          izz="0.0010527" />
      </inertial>
    
    <visual>
      <origin xyz="0 0 0" rpy="0 0 0" />
      <geometry>
        <mesh filename="package://jaka_zu3_myurdf/meshes/Link_1.STL" />
      </geometry>
      <material
        name="Link_1Color">
        <color
          rgba="1 1 1 1" />
      </material>
    </visual>
    <collision>
      <origin xyz="0 0 0" rpy="0 0 0" />
      <geometry>
        <mesh filename="package://jaka_zu3_myurdf/meshes/Link_1.STL" />
      </geometry>
    </collision>
    <!-- <xacro:cylinder_inertial radius="0.04" length="0.118" mass="${link1_mass}" /> -->
  </link>
  <gazebo reference="Link_1">
    <!-- <selfCollide>true</selfCollide> -->
    <meterial>Gazebo/Grey</meterial>
  </gazebo>

  <joint name="joint_1" type="revolute">
    <origin xyz="0 0 0.15055" rpy="0 0 0" />
    <parent link="Link_0" />
    <child link="Link_1" />
    <axis xyz="0 0 1" />
    <limit
      lower="-4.71"
      upper="4.71"
      effort="300"
      velocity="3.14" />
    <dynamics
      damping="50"
      friction="1" />
    <!-- <safety_controller 
      soft_lower_limit="${joint_1_lower_limit + safety_pos_margin}" 
      soft_upper_limit="${joint_1_upper_limit - safety_pos_margin}" 
      k_position="${safety_k_position}" 
      k_velocity="0.0"/> -->
  </joint>

  <link name="Link_2">
    <inertial>
        <origin
          xyz="0.114 -5.5358E-07 -0.11162"
          rpy="0 0 0" />
        <mass
          value="2.3202" />
        <inertia
          ixx="0.0032518"
          ixy="1.6898E-08"
          ixz="-3.3843E-06"
          iyy="0.0045664"
          iyz="9.1919E-09"
          izz="0.0035107" />
      </inertial>
    <visual>
      <origin xyz="0 0 0" rpy="0 0 0" />
      <geometry>
        <mesh filename="package://jaka_zu3_myurdf/meshes/Link_2.STL" />
      </geometry>
      <material
        name="Link_2Color">
        <color
          rgba="1 1 1 1" />
      </material>
    </visual>
    <collision>
      <origin xyz="0 0 0" rpy="0 0 0" />
      <geometry>
        <mesh filename="package://jaka_zu3_myurdf/meshes/Link_2.STL" />
      </geometry>
    </collision>
    <!-- <xacro:cylinder_inertial radius="0.04" length="0.254" mass="${link2_mass}" /> -->
  </link>
  <gazebo reference="Link_2">
    <!-- <selfCollide>true</selfCollide> -->
    <meterial>Gazebo/Grey</meterial>
  </gazebo> 
  
  <joint name="joint_2" type="revolute">
    <origin xyz="0 0 0" rpy="1.5708 0 0" />
    <parent link="Link_1" />
    <child link="Link_2" />
    <axis xyz="0 0 1" />
    <limit
      lower="-1.48"
      upper="4.62"
      effort="300"
      velocity="3.14" />
    <dynamics
      damping="50"
      friction="1" />
    <!-- <safety_controller 
      soft_lower_limit="${joint_2_lower_limit + safety_pos_margin}" 
      soft_upper_limit="${joint_2_upper_limit - safety_pos_margin}" 
      k_position="${safety_k_position}" 
      k_velocity="0.0"/> -->
  </joint>

  <link name="Link_3">
    <inertial>
        <origin
          xyz="0 0 0"
          rpy="0 0 0" />
        <mass
          value="1.2034" />
        <inertia
          ixx="0.00093819"
          ixy="1.276E-07"
          ixz="-0.00033673"
          iyy="0.0038664"
          iyz="5.3811E-08"
          izz="0.0036229" />
      </inertial>
    
    <visual>
      <origin xyz="0 0 0" rpy="0 0 0" />
      <geometry>
        <mesh filename="package://jaka_zu3_myurdf/meshes/Link_3.STL" />
      </geometry>
      <material
        name="Link_3Color">
        <color
          rgba="1 1 1 1" />
      </material>
    </visual>
    <collision>
      <origin xyz="0 0 0" rpy="0 0 0" />
      <geometry>
        <mesh filename="package://jaka_zu3_myurdf/meshes/Link_3.STL" />
      </geometry>
    </collision>
    <!-- <xacro:cylinder_inertial radius="0.035" length="0.235" mass="${link3_mass}" /> -->
  </link>
  <gazebo reference="Link_3">
    <!-- <selfCollide>true</selfCollide> -->
    <meterial>Gazebo/Grey</meterial>
  </gazebo> 

  <joint name="joint_3" type="revolute">
    <origin xyz="0.246 0 0" rpy="0 0 0" />
    <parent link="Link_2" />
    <child link="Link_3" />
    <axis xyz="0 0 1" />
    <limit lower="-3.05" upper="3.05" effort="330" velocity="3.14" />
    <dynamics damping="50" friction="1" />
    <!-- <safety_controller 
      soft_lower_limit="${joint_3_lower_limit + safety_pos_margin}" 
      soft_upper_limit="${joint_3_upper_limit - safety_pos_margin}" 
      k_position="${safety_k_position}" 
      k_velocity="0.0"/> -->
  </joint>

  <link name="Link_4">
    <inertial>
        <origin
          xyz="6.5395E-08 -0.014051 0.0031609"
          rpy="0 0 0" />
        <mass
          value="0.49334" />
        <inertia
          ixx="0.00050163"
          ixy="-3.5155E-09"
          ixz="-2.6858E-09"
          iyy="0.00032415"
          iyz="-6.2159E-05"
          izz="0.00047909" />
      </inertial>
    
    <visual>
      <origin xyz="0 0 0" rpy="0 0 0" />
      <geometry>
        <mesh filename="package://jaka_zu3_myurdf/meshes/Link_4.STL" />
      </geometry>
      <material
        name="Link_4Color">
        <color
          rgba="1 1 1 1" />
      </material>
    </visual>
    <collision>
      <origin xyz="0 0 0" rpy="0 0 0" />
      <geometry>
        <mesh filename="package://jaka_zu3_myurdf/meshes/Link_4.STL" />
      </geometry>
    </collision>
    <!-- <xacro:cylinder_inertial radius="0.03" length="0.1175" mass="${link4_mass}" /> -->
  </link>
  <gazebo reference="Link_4">
    <!-- <selfCollide>true</selfCollide> -->
    <meterial>Gazebo/Grey</meterial>
  </gazebo>

  <joint name="joint_4" type="revolute">
    <origin xyz="0.228 0 -0.113" rpy="0 0 0" />
    <parent link="Link_3" />
    <child link="Link_4" />
    <axis xyz="0 0 1" />
    <limit lower="-1.48" upper="4.62" effort="330" velocity="3.14" />
    <dynamics damping="50" friction="1" />
    <!-- <safety_controller 
      soft_lower_limit="${joint_4_lower_limit + safety_pos_margin}" 
      soft_upper_limit="${joint_4_upper_limit - safety_pos_margin}" 
      k_position="${safety_k_position}" 
      k_velocity="0.0"/> -->
  </joint>

  <link name="Link_5">
    <inertial>
        <origin
          xyz="2.5684E-07 0.0068642 -0.0021581"
          rpy="0 0 0" />
        <mass
          value="0.55082" />
        <inertia
          ixx="0.0010014"
          ixy="4.8947E-09"
          ixz="4.7274E-10"
          iyy="0.00036028"
          iyz="-1.6847E-05"
          izz="0.0009728" />
      </inertial>
    
    <visual>
      <origin xyz="0 0 0" rpy="0 0 0" />
      <geometry>
        <mesh filename="package://jaka_zu3_myurdf/meshes/Link_5.STL" />
      </geometry>
      <material
        name="Link_5Color">
        <color
          rgba="1 1 1 1" />
      </material>
    </visual>
    <collision>
      <origin xyz="0 0 0" rpy="0 0 0" />
      <geometry>
        <mesh filename="package://jaka_zu3_myurdf/meshes/Link_5.STL" />
      </geometry>
    </collision>
    <!-- <xacro:cylinder_inertial radius="0.03" length="0.1175" mass="${link5_mass}" /> -->
  </link>
  <gazebo reference="Link_5">
    <!-- <selfCollide>true</selfCollide> -->
    <meterial>Gazebo/Grey</meterial>
  </gazebo>

  <joint name="joint_5" type="revolute">
    <origin xyz="0 -0.11675 0" rpy="1.5708 0 0" />
    <parent link="Link_4" />
    <child link="Link_5" />
    <axis xyz="0 0 1" />
    <limit lower="-4.71" upper="4.71" effort="330" velocity="3.83" />
    <dynamics damping="50" friction="1" />
    <!-- <safety_controller 
      soft_lower_limit="${joint_5_lower_limit + safety_pos_margin}" 
      soft_upper_limit="${joint_5_upper_limit - safety_pos_margin}" 
      k_position="${safety_k_position}" 
      k_velocity="0.0"/> -->
  </joint>

  <link name="Link_6">
    <inertial>
        <origin
          xyz="5.2572E-05 -0.0001007 -0.0091035"
          rpy="0 0 0" />
        <mass
          value="0.094884" />
        <inertia
          ixx="3.2886E-05"
          ixy="-8.8218E-08"
          ixz="-5.2215E-08"
          iyy="3.3701E-05"
          iyz="2.9383E-07"
          izz="5.458E-05" />
      </inertial>
    
    <visual>
      <origin xyz="0 0 0" rpy="0 0 0" />
      <geometry>
        <mesh filename="package://jaka_zu3_myurdf/meshes/Link_6.STL" />
      </geometry>
      <material
        name="Link_6Color">
        <color
          rgba="1 1 1 1" />
      </material>
    </visual>
    <collision>
      <origin xyz="0 0 0" rpy="0 0 0" />
      <geometry>
        <mesh filename="package://jaka_zu3_myurdf/meshes/Link_6.STL" />
      </geometry>
    </collision>
    <!-- <xacro:cylinder_inertial radius="0.03" length="0.105" mass="${link6_mass}" /> -->
  </link>
  <gazebo reference="Link_6">
    <!-- <selfCollide>true</selfCollide> -->
    <meterial>Gazebo/Grey</meterial>
  </gazebo>


  <joint name="joint_6" type="revolute">
    <origin
      xyz="0 0.0985 0"
      rpy="-1.5708 0 0" />
    <parent link="Link_5" />
    <child link="Link_6" />
    <axis xyz="0 0 -1" />
    <limit lower="${-2 * pi}" upper="${2 * pi}" effort="330" velocity="3.14" />
    <dynamics damping="50" friction="1" />
    <!-- <safety_controller 
      soft_lower_limit="${joint_6_lower_limit + safety_pos_margin}" 
      soft_upper_limit="${joint_6_upper_limit - safety_pos_margin}" 
      k_position="${safety_k_position}" 
      k_velocity="0.0"/> -->
  </joint>

  
  <!-- camera_link -->
  <link name="camera_link">
    <visual>
      <geometry>
        <box size="0.01 0.025 0.025" />
      </geometry>
      <origin xyz="0.0 0.0 0.0" rpy="0.0 0.0 0.0" />
      <meterial name="black" />
    </visual>
  </link>

  <joint name="camera_joint" type="fixed" >
    <parent link="Link_6" />
    <child link="camera_link" />
    <origin xyz="0 0 0" rpy="0 0 0" />
  </joint>
  <!-- ##################### -->

  <link name="world" />

  <joint name="world_joint" type="fixed">
    <parent link="world" />
    <!-- <child link = "plain_link" /> -->
    <child link = "Link_0" />
    <origin xyz="0.0 0.0 0.0" rpy="0.0 0.0 0.0" />
  </joint>


  <xacro:macro name="arm_transmission" params="joint_name">

      <transmission name="trans">
          <type>transmission_interface/SimpleTransmission</type>
          <joint name="${joint_name}">
            <hardwareInterface>hardware_interface/EffortJointInterface</hardwareInterface>
          </joint>
          <actuator name="motor">
            <hardwareInterface>hardware_interface/EffortJointInterface</hardwareInterface>
            <mechanicalReduction>1</mechanicalReduction>
          </actuator>
      </transmission>
  </xacro:macro>

    <xacro:arm_transmission joint_name='joint_1' />
    <xacro:arm_transmission joint_name='joint_2' />
    <xacro:arm_transmission joint_name='joint_3' />
    <xacro:arm_transmission joint_name='joint_4' />
    <xacro:arm_transmission joint_name='joint_5' />
    <xacro:arm_transmission joint_name='joint_6' />

</robot>
